Workbook

Sheet Indicadores (2)
C2: Mes | D2: Marzo
C3: Año | D3: 2024 | P3: =UPPER(LEFT(TEXT(TODAY(),"dddd dd ""de"" mmmm ""de"" yyyy"),1))& RIGHT(TEXT(TODAY(),"dddd dd ""de"" mmmm ""de"" yyyy"), LEN(TEXT(TODAY(),"dddd dd ""de"" mmmm ""de"" yyyy"))-1) -> Sábado 05 de septiembre de 2026
B8: Clima organizacional
B33: Plan de formación
B60: Costo de capacitación por empleado
X61: Mes | Y61: Año
B87: Tiempo promedio de capacitación (días)
X88: Mes | Y88: Año
B116: Índice de accidentes laborales
X117: Mes | Y117: Año
X145: Mes | Y145: Año

Sheet Indicadores
C2: Mes | D2: Diciembre | Z2: =D9&D10 -> Trimestre 12025
C3: Año | D3: 2025 | P3: =UPPER(LEFT(TEXT(TODAY(),"dddd dd ""de"" mmmm ""de"" yyyy"),1))& RIGHT(TEXT(TODAY(),"dddd dd ""de"" mmmm ""de"" yyyy"), LEN(TEXT(TODAY(),"dddd dd ""de"" mmmm ""de"" yyyy"))-1) -> Sábado 05 de septiembre de 2026 | Z3: Área | AA3: % área | AB3: Objetivo
Y4: =+$Z$2&Z4 -> Trimestre 12025Operaciones | Z4: Operaciones | AA4: =+VLOOKUP(Y4,'Clima organizacional'!A:I,7,FALSE) -> #N/A | AB4: =+VLOOKUP(Y4,'Clima organizacional'!A:I,9,FALSE) -> #N/A
Y5: =+$Z$2&Z5 -> Trimestre 12025Mantenimiento | Z5: Mantenimiento | AA5: =+VLOOKUP(Y5,'Clima organizacional'!A:I,7,FALSE) -> #N/A | AB5: =+VLOOKUP(Y5,'Clima organizacional'!A:I,9,FALSE) -> #N/A
Y6: =+$Z$2&Z6 -> Trimestre 12025Administración | Z6: Administración | AA6: =+VLOOKUP(Y6,'Clima organizacional'!A:I,7,FALSE) -> #N/A | AB6: =+VLOOKUP(Y6,'Clima organizacional'!A:I,9,FALSE) -> #N/A
B7: Clima organizacional | Y7: =+$Z$2&Z7 -> Trimestre 12025Ventas / Comercial | Z7: Ventas / Comercial | AA7: =+VLOOKUP(Y7,'Clima organizacional'!A:I,7,FALSE) -> #N/A | AB7: =+VLOOKUP(Y7,'Clima organizacional'!A:I,9,FALSE) -> #N/A
Y8: =+$Z$2&Z8 -> Trimestre 12025RRHH y Calidad | Z8: RRHH y Calidad | AA8: =+VLOOKUP(Y8,'Clima organizacional'!A:I,7,FALSE) -> #N/A | AB8: =+VLOOKUP(Y8,'Clima organizacional'!A:I,9,FALSE) -> #N/A
C9: Trimestre | D9: Trimestre 1
C10: Año | D10: 2025
Y11: Plan de formación
Y13: =DATE(D3,MATCH(D2,Listas!C2:C13,0),1) -> 45992
X14: Mes | Y14: Año | Z14: Mes | AA14: Capacitaciones Planificadas | AB14: Capacitaciones Realizadas | AC14: Cumplimiento (%) | AD14: Objetivo
X15: =CONCATENATE(Z15," ",Y15) -> Sin datos | Y15: {=IFERROR(_xlfn._xlws.FILTER('Plan de formación'!A2:F25,('Plan de formación'!G2:G25<=Indicadores!Y13)*('Plan de formación'!G2:G25>EDATE(Indicadores!Y13,-13))),"Sin datos")} -> Sin datos
X16: =CONCATENATE(Z16," ",Y16)
X17: =CONCATENATE(Z17," ",Y17)
X18: =CONCATENATE(Z18," ",Y18)
X19: =CONCATENATE(Z19," ",Y19)
X20: =CONCATENATE(Z20," ",Y20)
X21: =CONCATENATE(Z21," ",Y21)
X22: =CONCATENATE(Z22," ",Y22)
X23: =CONCATENATE(Z23," ",Y23)
X24: =CONCATENATE(Z24," ",Y24)
X25: =CONCATENATE(Z25," ",Y25)
X26: =CONCATENATE(Z26," ",Y26)
X27: =CONCATENATE(Z27," ",Y27)
Y30: Costos de capacitacion
B31: Plan de formación
X32: Mes | Y32: Año | Z32: Mes | AA32: Papelería ($) | AB32: Cursos ($) | AC32: Exámenes ($) | AD32: Total capacitación ($) | AE32: Empleados capacitados | AF32: Costo por empleado ($)
X33: =CONCATENATE(Z33," ",Y33) -> Sin datos | Y33: {=IFERROR(_xlfn._xlws.FILTER('Costo de capacitación'!A2:M25,('Costo de capacitación'!N2:N25<=Indicadores!Y13)*('Costo de capacitación'!N2:N25>EDATE(Indicadores!Y13,-13))),"Sin datos")} -> Sin datos
X34: =CONCATENATE(Z34," ",Y34)
X35: =CONCATENATE(Z35," ",Y35)
X36: =CONCATENATE(Z36," ",Y36)
X37: =CONCATENATE(Z37," ",Y37)
X38: =CONCATENATE(Z38," ",Y38)
X39: =CONCATENATE(Z39," ",Y39)
X40: =CONCATENATE(Z40," ",Y40)
X41: =CONCATENATE(Z41," ",Y41)
X42: =CONCATENATE(Z42," ",Y42)
X43: =CONCATENATE(Z43," ",Y43)
X44: =CONCATENATE(Z44," ",Y44)
...

Sheet Listas
A1: Trimestre | B1: Año | C1: Mes
A2: Trimestre 1 | B2: 2024 | C2: Enero
A3: Trimestre 2 | B3: 2025 | C3: Febrero
A4: Trimestre 3 | B4: 2026 | C4: Marzo
A5: Trimestre 4 | B5: 2027 | C5: Abril
B6: 2028 | C6: Mayo
B7: 2029 | C7: Junio
B8: 2030 | C8: Julio
C9: Agosto
C10: Septiembre
C11: Octubre
C12: Noviembre
C13: Diciembre

Sheet Clima organizacional
B1: Año | C1: Trimestre | D1: Área | E1: Respondientes | F1: Promedio pts | G1: % área | H1: Objetivo | I1: Objetivo%

Sheet Plan de formación
A1: Año | B1: Mes | C1: Capacitaciones Planificadas | D1: Capacitaciones Realizadas | E1: Cumplimiento (%) | F1: Objetivo | G1: Fecha | H1: Observaciones
A2: 2026 | B2: Agosto | C2: 12 | D2: 12 | E2: =D2/C2 -> 1 | F2: 0.95 | G2: =DATE(A2,MATCH(B2,[1]Listas!$C$2:$C$13,0),1) -> 46235

Sheet Costo de capacitación
A1: Año | B1: Mes | C1: Papelería o material de cursos ($) | D1: Cursos ($) | E1: Traslados Internos ($) | F1: Locativos ($) | G1: Plan padrino PDV ($) | H1: Cursos de Alturas ($) | I1: Curso coord. Altura ($) | J1: Curso BPM ($) | K1: Total capacitación ($) | L1: Empleados capacitados | M1: Costo por empleado ($) | N1: Fecha
A2: 2026 | B2: Agosto | C2: 28600 | D2: 0 | G2: 466825 | H2: 166600 | I2: 0 | J2: 1032000 | K2: =+SUM(C2:J2) -> 1694025 | L2: 75 | M2: =K2/L2 -> 22587 | N2: =DATE(A2,MATCH(B2,[1]Listas!$C$2:$C$13,0),1) -> 46235
K3: =+SUM(C3:J3) -> 0 | M3: =K3/L3 -> #DIV/0! | N3: =DATE(A3,MATCH(B3,Listas!$C$2:$C$13,0),1) -> #N/A
K4: =+SUM(C4:J4) -> 0 | M4: =K4/L4 -> #DIV/0! | N4: =DATE(A4,MATCH(B4,Listas!$C$2:$C$13,0),1) -> #N/A
K5: =+SUM(C5:J5) -> 0 | M5: =K5/L5 -> #DIV/0! | N5: =DATE(A5,MATCH(B5,Listas!$C$2:$C$13,0),1) -> #N/A
K6: =+SUM(C6:J6) -> 0 | M6: =K6/L6 -> #DIV/0! | N6: =DATE(A6,MATCH(B6,Listas!$C$2:$C$13,0),1) -> #N/A
K7: =+SUM(C7:J7) -> 0 | M7: =K7/L7 -> #DIV/0! | N7: =DATE(A7,MATCH(B7,Listas!$C$2:$C$13,0),1) -> #N/A
K8: =+SUM(C8:J8) -> 0 | M8: =K8/L8 -> #DIV/0! | N8: =DATE(A8,MATCH(B8,Listas!$C$2:$C$13,0),1) -> #N/A
K9: =+SUM(C9:J9) -> 0 | M9: =K9/L9 -> #DIV/0! | N9: =DATE(A9,MATCH(B9,Listas!$C$2:$C$13,0),1) -> #N/A
K10: =+SUM(C10:J10) -> 0 | M10: =K10/L10 -> #DIV/0! | N10: =DATE(A10,MATCH(B10,Listas!$C$2:$C$13,0),1) -> #N/A
K11: =+SUM(C11:J11) -> 0 | M11: =K11/L11 -> #DIV/0! | N11: =DATE(A11,MATCH(B11,Listas!$C$2:$C$13,0),1) -> #N/A
K12: =+SUM(C12:J12) -> 0 | M12: =K12/L12 -> #DIV/0! | N12: =DATE(A12,MATCH(B12,Listas!$C$2:$C$13,0),1) -> #N/A
K13: =+SUM(C13:J13) -> 0 | M13: =K13/L13 -> #DIV/0! | N13: =DATE(A13,MATCH(B13,Listas!$C$2:$C$13,0),1) -> #N/A
K14: =+SUM(C14:J14) -> 0 | M14: =K14/L14 -> #DIV/0! | N14: =DATE(A14,MATCH(B14,Listas!$C$2:$C$13,0),1) -> #N/A
... K25: =+SUM(C25:J25) -> 0 | M25: =K25/L25 -> #DIV/0! | N25: =DATE(A25,MATCH(B25,Listas!$C$2:$C$13,0),1) -> #N/A

Sheet  Costo de contratación 
A2: Año | B2: Mes | C2: Vacante | D2: Costo examenes medicos Mujer | E2: Costo examenes medicos Hombre | F2: Estudio de confiabilidad | G2: Dotacion | H2: Total costo contracion | I2: total costo contra mujer | J2: total costo hombre | K2: empleados mujer | L2: empleados hombre | M2: total empleados contratados | N2: Costo por empleado ($)
A3: 2026 | B3: Agosto | C3: Auxiliar de cocina | D3: 102850 | E3: 83067 | F3: 0 | G3: 355167 | H3: =+SUM(D3:G3) -> 541084 | I3: =D3*K3 -> 1748450 | J3: =E3*L3 -> 1827474 | K3: 17 | L3: 22 | M3: 39 | N3: =(I3+J3)/M3 -> 91690.359
A4: 2026 | B4: Agosto | C4: Auxiliar de servicio | D4: 102850 | E4: 83067 | F4: 0 | G4: 198730 | H4: =+SUM(D4:G4) -> 384647 | I4: =D4*K4 -> 1131350 | J4: =E4*L4 -> 332268 | K4: 11 | L4: 4 | M4: 15 | N4: =(I4+J4)/M4 -> 97574.533
G5: =+SUM(D5:F5) -> 0 | I5: =G5/H5 -> #DIV/0!
G6: =+SUM(D6:F6) -> 0 | I6: =G6/H6 -> #DIV/0!
G7: =+SUM(D7:F7) -> 0 | I7: =G7/H7 -> #DIV/0!
G8: =+SUM(D8:F8) -> 0 | I8: =G8/H8 -> #DIV/0!
G9: =+SUM(D9:F9) -> 0 | I9: =G9/H9 -> #DIV/0!
G10: =+SUM(D10:F10) -> 0 | I10: =G10/H10 -> #DIV/0!
G11: =+SUM(D11:F11) -> 0 | I11: =G11/H11 -> #DIV/0!
G12: =+SUM(D12:F12) -> 0 | I12: =G12/H12 -> #DIV/0!
G13: =+SUM(D13:F13) -> 0 | I13: =G13/H13 -> #DIV/0!
G14: =+SUM(D14:F14) -> 0 | I14: =G14/H14 -> #DIV/0!
G15: =+SUM(D15:F15) -> 0 | I15: =G15/H15 -> #DIV/0!
G16: =+SUM(D16:F16) -> 0 | I16: =G16/H16 -> #DIV/0!
... G50: =+SUM(D50:F50) -> 0 | I50: =G50/H50 -> #DIV/0!

Sheet SST
A1: Año | B1: Mes | C1: Fecha | D1: Día del accidente | E1: Cedula | F1: Nombre | G1: Cargo | H1: Proceso | I1: Punto de venta | J1: Accidente | K1: Causal | L1: tipo de accidente | M1: severidad
A2: 2026 | B2: Agosto | C2: 46235 | D2: Sabado | E2: 1122822082 | F2: Loizy Jailen Arzuaga Vasquez | G2: Auxiliar de cocina | H2: PDV | I2: Aventura | J2: Golpeado por objeto que cae | K2: Manipulación de platos ubicados en una repisa a una altura elevada, generando caída de los objetos | L2: Leve | M2: 3
A3: 2026 | B3: Agosto | C3: 46240 | D3: Jueves | E3: 1043436854 | F3: Santiago José Hoyos Barilla | G3: Auxiliar de logistica | H3: Logisitca | I3: Logisitca | J3: Golpeado por objeto que cae | K3: Caida de objetos por manipulación en area de logisitca | L3: Leve | M3: 1
A4: 2026 | B4: Agosto | C4: 46242 | D4: Sabado | E4: 1105926744 | F4: Angie Karelly Mora Garcia | G4: Auxiliar de cocina | H4: PDV | I4: Jardin Plaza | J4: Contacto con sustancia caliente | K4: Manipulación de recipiente con aceite caliente ubicado en la parte superior del horno, ocasionando derrame de aceite | L4: Leve | M4: 2
A5: 2026 | B5: Agosto | C5: 46249 | D5: Sabado | E5: 1003358035 | F5: Andy Luz Vergara Lambraño | G5: Auxiliar de servicio | H5: PDV | I5: Viva Laureles | J5: Caida al mismo nivel | K5: Caida a nivel por resbalon | L5: Leve | M5: 3
A6: 2026 | B6: Agosto | C6: 46260 | D6: Miercoles | E6: 1000547526 | F6: Santiago Gil Maldonado | G6: Aprendiz de mantenimiento | H6: Administrativo | I6: Administrativo | J6: Contacto con elementos cortopunzantes | K6: Manipuación de laminas de aluminio con bordes expuestos ocasionando corte | L6: Leve | M6: 30

Sheet Ausentismo
A1: Año | B1: Mes | C1: Concepto | D1: Días | E1: Valor($)
A2: 2026 | B2: JUNIO | C2: AUSENCIA SIN SOPORTE | D2: 139
A3: 2026 | B3: JUNIO | C3: CALAMIDAD DOMESTICA | D3: 15 | E3: 875454
A4: 2026 | B4: JUNIO | C4: INCAPACIDAD ACC LABORAL | D4: 33 | E4: 2195027
A5: 2026 | B5: JUNIO | C5: INCAPACIDAD EMPR DIAS | D5: 0 | E5: 11717050
A6: 2026 | B6: JUNIO | C6: INCAPACIDAD GENERAL | D6: 478 | E6: 13434510
A7: 2026 | B7: JUNIO | C7: LICENCIA DE MATERNIDAD | D7: 60 | E7: 4527416
A8: 2026 | B8: JUNIO | C8: LICENCIA DE PATERNIDAD
A9: 2026 | B9: JUNIO | C9: LICENCIA NO REMUNERADA | D9: 30
A10: 2026 | B10: JUNIO | C10: LICENCIA POR LUTO | D10: 25 | E10: 1628954
A11: 2026 | B11: JUNIO | C11: PERDIDA DOMINICAL | D11: 2
A12: 2026 | B12: JUNIO | C12: PERMISO REMUNERADO
A13: 2026 | B13: JUNIO | C13: SUSPENSION | D13: 4
A14: 2026 | B14: JUNIO | C14: VACACIONES | D14: 211 | E14: 11254197
A15: 2026 | B15: JUNIO | C15: VACACIONES DIAS NO HABILES | D15: 0 | E15: 3358462
A16: 2026 | B16: JULIO | C16: AUSENCIA SIN SOPORTE | D16: 147
A17: 2026 | B17: JULIO | C17: CALAMIDAD DOMESTICA | D17: 20 | E17: 1169208
A18: 2026 | B18: JULIO | C18: INCAPACIDAD ACC LABORAL | D18: 45 | E18: 3333976
A19: 2026 | B19: JULIO | C19: INCAPACIDAD EMPR DIAS | D19: 0 | E19: 9582192
A20: 2026 | B20: JULIO | C20: INCAPACIDAD GENERAL | D20: 461 | E20: 13259395
A21: 2026 | B21: JULIO | C21: LICENCIA DE MATERNIDAD | D21: 62 | E21: 4678330
A22: 2026 | B22: JULIO | C22: LICENCIA DE PATERNIDAD
A23: 2026 | B23: JULIO | C23: LICENCIA NO REMUNERADA | D23: 7
A24: 2026 | B24: JULIO | C24: LICENCIA POR LUTO | D24: 5 | E24: 291818
A25: 2026 | B25: JULIO | C25: PERDIDA DOMINICAL
A26: 2026 | B26: JULIO | C26: PERMISO REMUNERADO
A27: 2026 | B27: JULIO | C27: SUSPENSION
A28: 2026 | B28: JULIO | C28: VACACIONES | D28: 370 | E28: 20530622
A29: 2026 | B29: JULIO | C29: VACACIONES DIAS NO HABILES | D29: 0 | E29: 3869100
A30: 2026 | B30: AGOSTO | C30: AUSENCIA SIN SOPORTE | D30: 159
A31: 2026 | B31: AGOSTO | C31: CALAMIDAD DOMESTICA | D31: 3 | E31: 175091
A32: 2026 | B32: AGOSTO | C32: INCAPACIDAD ACC LABORAL | D32: 9 | E32: 601535
A33: 2026 | B33: AGOSTO | C33: INCAPACIDAD EMPR DIAS | D33: 3 | E33: 10086140
A34: 2026 | B34: AGOSTO | C34: INCAPACIDAD GENERAL | D34: 477 | E34: 12607451
A35: 2026 | B35: AGOSTO | C35: LICENCIA DE MATERNIDAD | D35: 38 | E35: 2949266
A36: 2026 | B36: AGOSTO | C36: LICENCIA DE PATERNIDAD | D36: 14 | E36: 817089
A37: 2026 | B37: AGOSTO | C37: LICENCIA NO REMUNERADA | D37: 3
A38: 2026 | B38: AGOSTO | C38: LICENCIA POR LUTO
A39: 2026 | B39: AGOSTO | C39: PERDIDA DOMINICAL
A40: 2026 | B40: AGOSTO | C40: PERMISO REMUNERADO | D40: 6 | E40: 350183
...

Sheet Costo de Bonificación
A1: Año | B1: Mes | C1: Concepto | D1: valor | E1: factor prestacional | F1: total costo | G1: nota | J1: FACTOR PRESTACIONAL
A2: 2026 | B2: AGOSTO | C2: BONIFICACION NO SALARIAL | D2: 5401683 | F2: =SUM(D2:E2) -> 5401683 | G2: 20 % adiciones y bonificación de Junior de produccion y Logistica y ajustes de meses pasados | J2: CESANTIAS | K2: 0.0833 | L2: VACACIONES | M2: 0.0417 | N2: CAJA | O2: 0.04
A3: 2026 | B3: AGOSTO | C3: BONIFICACION RECREACION ALIMENTACION | D3: 19306400 | F3: =SUM(D3:E3) -> 19306400 | J3: INTERESES | K3: 0.01 | L3: PENSION | M3: 0.12
A4: 2026 | B4: AGOSTO | C4: BONIFICACION POR ADICIONES | D4: 22103597 | E4: =D4*$O$4 -> 8592552.3 | F4: =SUM(D4:E4) -> 30696149 | J4: PRIMA | K4: 0.0833 | L4: ARL | M4: 0.01044 | N4: TOTAL | O4: =+K2+K3+K4+M4+M3+M2+O2 -> 0.38874
A5: 2026 | B5: AGOSTO | C5: BONIFICACION POR CUMPLIMIENTO | D5: 83349958 | E5: =D5*$O$4 -> 32401463 | F5: =SUM(D5:E5) -> 1.1575142e+08
A6: 2026 | B6: AGOSTO | C6: PRIMA EXTRALEGAL TRIMESTRAL | D6: 57093333 | F6: =SUM(D6:E6) -> 57093333 | G6: Se pagará en Octubre
A7: 2026 | B7: JULIO | C7: BONIFICACION NO SALARIAL | D7: 69431717 | F7: =SUM(D7:E7) -> 69431717
A8: 2026 | B8: JULIO | C8: BONIFICACION RECREACION ALIMENTACION | D8: 18479500 | F8: =SUM(D8:E8) -> 18479500
A9: 2026 | B9: JULIO | C9: BONIFICACION POR ADICIONES | D9: 22349403 | E9: =D9*$O$4 -> 8688106.9 | F9: =SUM(D9:E9) -> 31037510
A10: 2026 | B10: JULIO | C10: BONIFICACION POR CUMPLIMIENTO | D10: 22044446 | E10: =D10*$O$4 -> 8569557.9 | F10: =SUM(D10:E10) -> 30614004
A11: 2026 | B11: JULIO | C11: PRIMA EXTRALEGAL TRIMESTRAL | D11: 50369716 | G11: Se pagará en Octubre
A12: 2026 | B12: JUNIO | C12: BONIFICACION NO SALARIAL | D12: 67745125 | F12: =SUM(D12:E12) -> 67745125
A13: 2026 | B13: JUNIO | C13: BONIFICACION RECREACION ALIMENTACION | D13: 22296400 | F13: =SUM(D13:E13) -> 22296400
A14: 2026 | B14: JUNIO | C14: BONIFICACION POR ADICIONES | D14: 24068362 | E14: =D14*$O$4 -> 9356335 | F14: =SUM(D14:E14) -> 33424697
A15: 2026 | B15: JUNIO | C15: BONIFICACION POR CUMPLIMIENTO | D15: 22308967 | E15: =D15*$O$4 -> 8672387.8 | F15: =SUM(D15:E15) -> 30981355
A16: 2026 | B16: JUNIO | C16: PRIMA EXTRALEGAL TRIMESTRAL | D16: =48922682+166471 -> 49089153 | G16: Pagada en Julio
A17: 2026 | B17: MAYO | C17: BONIFICACION NO SALARIAL | D17: 65462889 | F17: =SUM(D17:E17) -> 65462889
A18: 2026 | B18: MAYO | C18: BONIFICACION RECREACION ALIMENTACION | D18: 19537400 | F18: =SUM(D18:E18) -> 19537400
A19: 2026 | B19: MAYO | C19: BONIFICACION POR ADICIONES | D19: 19897012 | E19: =D19*$O$4 -> 7734764.4 | F19: =SUM(D19:E19) -> 27631776
A20: 2026 | B20: MAYO | C20: BONIFICACION POR CUMPLIMIENTO | D20: 21447955 | E20: =D20*$O$4 -> 8337678 | F20: =SUM(D20:E20) -> 29785633
A21: 2026 | B21: MAYO | C21: PRIMA EXTRALEGAL TRIMESTRAL | D21: 56210831 | G21: Pagada en Julio

Sheet Cobro de incapacidades
A1: Mes | B1: Año | C1: Cédula del empleado con novedad | D1: Nombre del colaborador | E1: Tipo de Novedad | F1: Fecha inicio de Novedad | G1: Fecha fin de Novedad | H1: Dias de novedad | I1: Eps | J1: Radicado / Tramite | K1: Gestiona S/N | L1: Fecha de radicado | M1: Observación | N1: Salario | O1: Dias a cobrar | P1: Valor a recuperar | Q1: Valor pagado | R1: Fecha de pago | S1: Estado del pago
A2: Mayo | B2: 2026 | C2: 1144108129 | D2: TULANDE GUERRERO MAIRA ISABELA | E2: INCAPACIDAD GENERAL | F2: 46144 | G2: 46146 | H2: 3 | I2: COMFENALCO VALLE EPS | J2: RADICADO POR CORREO | K2: SI | L2: 46173 | M2: servicioalcliente@comfenalcovalle.com.co | N2: 1750905 | O2: 1 | P2: 58363.5
A3: Mayo | B3: 2026 | C3: 1018481219 | D3: ROJAS ORTIZ LINDA STEFANNY | E3: INCAPACIDAD GENERAL | F3: 46162 | G3: 46171 | H3: 10 | I3: COMPENSAR | J3: EN20260000479180 | K3: SI | L3: 46173 | N3: 1750905 | O3: 8 | P3: 466908 | Q3: 583635 | R3: 46189 | S3: PAGADA
A4: Mayo | B4: 2026 | C4: 1018481219 | D4: ROJAS ORTIZ LINDA STEFANNY | E4: INCAPACIDAD GENERAL | F4: 46159 | G4: 46161 | H4: 3 | I4: COMPENSAR | J4: EN20260000479180 | K4: SI | L4: 46173 | N4: 1750905 | O4: 1 | P4: 58363.5 | Q4: 58364 | R4: 46189 | S4: PAGADA
A5: Mayo | B5: 2026 | C5: 1016051919 | D5: GAVIRIA GARCIA CHRISTIAM ALEJANDRO | E5: INCAPACIDAD GENERAL | F5: 46145 | G5: 46156 | H5: 12 | I5: ENTIDAD PROMOTORA DE SALUD FAMISANAR LTDA CAFAM-COLSUBSIDIO | J5: RADICADO POR CORREO | K5: SI | L5: 46173 | M5: correspondencia@famisanar.com.co | N5: 2110000 | O5: 10 | P5: 583635 | Q5: 583635 | R5: 46185 | S5: PAGADA
A6: Mayo | B6: 2026 | C6: 1024523886 | D6: AGUIAR ARBELAEZ NEVER ANDRES | E6: INCAPACIDAD GENERAL | F6: 46147 | G6: 46149 | H6: 3 | I6: ENTIDAD PROMOTORA DE SALUD FAMISANAR LTDA CAFAM-COLSUBSIDIO | J6: RADICADO POR CORREO | K6: SI | L6: 46173 | M6: correspondencia@famisanar.com.co | N6: 1750905 | O6: 1 | P6: 58363.5
A7: Mayo | B7: 2026 | C7: 1143972724 | D7: MELO VARGAS KELLY JAZMIN | E7: INCAPACIDAD ACC LABORAL | F7: 46138 | G7: 46140 | H7: 3 | I7: ARL SURA | J7: 210383928734 | K7: SI | L7: 46173 | N7: 1750905 | O7: 3 | P7: 210984 | Q7: 210984 | R7: 46184 | S7: PAGADA
A8: Mayo | B8: 2026 | C8: 1024560775 | D8: TORRES BORRERO IVONNE NATALIA | E8: INCAPACIDAD GENERAL | F8: 46158 | G8: 46160 | H8: 3 | I8: ENTIDAD PROMOTORA DE SALUD SANITAS S.A | J8: 61899186 | K8: SI | L8: 46173 | N8: 1750905 | O8: 1 | P8: 58363.5
A9: Mayo | B9: 2026 | C9: 1055750969 | D9: REPISO GUZMAN ESTEFANIA | E9: INCAPACIDAD GENERAL | F9: 46163 | G9: 46166 | H9: 4 | I9: ENTIDAD PROMOTORA DE SALUD SANITAS S.A | J9: 61899188 | K9: SI | L9: 46173 | N9: 1750905 | O9: 2 | P9: 116727
A10: Mayo | B10: 2026 | C10: 1111539360 | D10: OSPINA RAMIREZ STEFANNY | E10: INCAPACIDAD GENERAL | F10: 46161 | G10: 46175 | H10: 15 | I10: ENTIDAD PROMOTORA DE SALUD SERVICIO OCCIDENTAL DE SALUD S.A | J10: 20260531-330869 | K10: SI | L10: 46173 | N10: 1750905 | O10: 13 | P10: 758725.5
A11: Mayo | B11: 2026 | C11: 1004774963 | D11: RODRIGUES MARTINEZ JHON MICHEL. | E11: INCAPACIDAD GENERAL | F11: 46165 | G11: 46168 | H11: 4 | I11: EPS SURA | J11: SOLICITADA TRANSCRITA POR LA PAGINA | K11: SI | L11: 46170 | N11: 1750905 | O11: 2 | P11: 116727
A12: Mayo | B12: 2026 | C12: 1143427761 | D12: RINCON GIRALDO DORA LISSETH | E12: INCAPACIDAD GENERAL | F12: 46157 | G12: 46163 | H12: 7 | I12: EPS SURA | J12: 11721058 | K12: SI | L12: 46170 | N12: 1750905 | O12: 5 | P12: 291817.5 | Q12: 408545 | R12: 46183 | S12: PAGADA
A13: Mayo | B13: 2026 | C13: 1001005095 | D13: GARCIA AGUIRRE DANIEL | E13: INCAPACIDAD GENERAL | F13: 46160 | G13: 46162 | H13: 3 | I13: EPS SURA | J13: SOLICITADA TRANSCRITA POR LA PAGINA | K13: SI | L13: 46170 | M13: daguirre0602@gmail.com | N13: 1750905 | O13: 1 | P13: 58363.5
A14: Mayo | B14: 2026 | C14: 1094289725 | D14: MONTILLA GONZALEZ MARLON HENRIQUE | E14: INCAPACIDAD ACC LABORAL | F14: 46154 | G14: 46156 | H14: 3 | I14: ARL SURA | J14: 220219438833 | K14: SI | L14: 46173 | N14: 1750905 | O14: 3 | P14: 178251 | Q14: 178251 | R14: 46184 | S14: PAGADA
A15: Mayo | B15: 2026 | C15: 1143427761 | D15: RINCON GIRALDO DORA LISSETH | E15: INCAPACIDAD GENERAL | F15: 46164 | G15: 46170 | H15: 7 | I15: EPS SURA | J15: 11721054 | K15: SI | L15: 46170 | N15: 1750905 | O15: 5 | P15: 291817.5 | Q15: 408545 | R15: 46183 | S15: PAGADA
A16: Mayo | B16: 2026 | C16: 1234190993 | D16: RAMIREZ VANEGAS DARLYN JOANNA. | E16: INCAPACIDAD ACC LABORAL | F16: 46156 | G16: 46159 | H16: 4 | I16: ARL SURA | J16: 290188919869 | K16: SI | L16: 46173 | N16: 1750905 | O16: 4 | P16: 262708 | Q16: 262708 | R16: 46184 | S16: PAGADA
A17: Mayo | B17: 2026 | C17: 1000413322 | D17: MADRIGAL LOPEZ JUAN CAMILO | E17: INCAPACIDAD ACC LABORAL | F17: 46157 | G17: 46163 | H17: 7 | I17: ARL SURA | J17: 158833687294 | K17: SI | L17: 46173 | N17: 1750905 | O17: 5 | P17: 492296 | Q17: 492296 | R17: 46184 | S17: PAGADA
A18: Mayo | B18: 2026 | C18: 1193263264 | D18: DUEÑAS OSORIO JHON ALEXANDER | E18: INCAPACIDAD GENERAL | F18: 46165 | G18: 46167 | H18: 3 | I18: NUEVA EPS | J18: 2484215 | K18: SI | L18: 46170 | N18: 1750905 | O18: 1 | P18: 58363.5
A19: Mayo | B19: 2026 | C19: 1143958740 | D19: LUJAN CARMEN LADY JOHANA | E19: INCAPACIDAD ACC LABORAL | F19: 46158 | G19: 46160 | H19: 3 | I19: ARL SURA | J19: 312637033005 | K19: SI | L19: 46173 | N19: 1750905 | O19: 3 | P19: 174132 | Q19: 174132 | R19: 46184 | S19: PAGADA
A20: Mayo | B20: 2026 | C20: 1143427761 | D20: RINCON GIRALDO DORA LISSETH | E20: INCAPACIDAD GENERAL | F20: 46143 | G20: 46149 | H20: 7 | I20: EPS SURA | J20: 11721075 | K20: SI | L20: 46170 | N20: 1750905 | O20: 5 | P20: 291817.5 | Q20: 408545 | R20: 46183 | S20: PAGADA
A21: Mayo | B21: 2026 | C21: 1143427761 | D21: RINCON GIRALDO DORA LISSETH | E21: INCAPACIDAD GENERAL | F21: 46150 | G21: 46156 | H21: 7 | I21: EPS SURA | J21: 11721065 | K21: SI | L21: 46170 | N21: 1750905 | O21: 5 | P21: 291817.5 | Q21: 408545 | R21: 46183 | S21: PAGADA
A22: Mayo | B22: 2026 | C22: 1111539998 | D22: VILLAMIL VIDAL ANGELLY SOFIA | E22: INCAPACIDAD GENERAL | F22: 46131 | G22: 46137 | H22: 7 | I22: EPS-S COOSALUD MOVILIDAD | J22: INC-00826854 | K22: SI | L22: 46173 | N22: 1750905 | O22: 5 | P22: 291817.5 | Q22: 291818 | R22: 46204 | S22: PAGADA
A23: Mayo | B23: 2026 | C23: 1111539998 | D23: VILLAMIL VIDAL ANGELLY SOFIA | E23: INCAPACIDAD GENERAL | F23: 46142 | G23: 46148 | H23: 7 | I23: EPS-S COOSALUD MOVILIDAD | J23: INC-00826855 | K23: SI | L23: 46173 | N23: 1750905 | O23: 5 | P23: 291817.5 | Q23: 408545 | R23: 46204 | S23: PAGADA
A24: Mayo | B24: 2026 | C24: 1111539998 | D24: VILLAMIL VIDAL ANGELLY SOFIA | E24: INCAPACIDAD GENERAL | F24: 46150 | G24: 46154 | H24: 5 | I24: EPS-S COOSALUD MOVILIDAD | J24: INC-00826856 | K24: SI | L24: 46173 | N24: 1750905 | O24: 3 | P24: 175090.5 | Q24: 291818 | R24: 46204 | S24: PAGADA
A25: Mayo | B25: 2026 | C25: 1111539998 | D25: VILLAMIL VIDAL ANGELLY SOFIA | E25: INCAPACIDAD GENERAL | F25: 46155 | G25: 46167 | H25: 13 | I25: EPS-S COOSALUD MOVILIDAD | J25: INC-00826858 | K25: SI | L25: 46173 | N25: 1750905 | O25: 11 | P25: 641998.5 | Q25: 875453 | R25: 46204 | S25: PAGADA
A26: Mayo | B26: 2026 | C26: 1001774476 | D26: JARAMILLO OSSA SARA PAULINA. | E26: INCAPACIDAD GENERAL | F26: 46164 | G26: 46166 | H26: 3 | I26: EPS-S COOSALUD MOVILIDAD | J26: INC-00826859 | K26: SI | L26: 46173 | N26: 1750905 | O26: 1 | P26: 58363.5 | Q26: 58364 | R26: 46204 | S26: PAGADA
A27: Mayo | B27: 2026 | C27: 1007524718 | D27: BURGOS CASTILLO VALENTINA | E27: INCAPACIDAD GENERAL | F27: 46157 | G27: 46159 | H27: 3 | I27: NUEVA EPS | J27: 2484221 | K27: SI | L27: 46170 | N27: 1750905 | O27: 1 | P27: 58363.5 | Q27: 58364 | R27: 46213 | S27: PAGADA
A28: Mayo | B28: 2026 | C28: 1192732878 | D28: BELLO GUZMAN CARLOS DAVID | E28: INCAPACIDAD GENERAL | F28: 46160 | G28: 46162 | H28: 3 | I28: NUEVA EPS | J28: 2484228 | K28: SI | L28: 46170 | N28: 1750905 | O28: 1 | P28: 58363.5
A29: Mayo | B29: 2026 | C29: 1143451286 | D29: HERNANDEZ GRANADILLO WENDY JOHANA | E29: INCAPACIDAD ACC LABORAL | F29: 46163 | G29: 46166 | H29: 4 | I29: ARL SURA | J29: 942491794501 | K29: SI | L29: 46173 | N29: 1750905 | O29: 4 | P29: 213502 | Q29: 213502 | R29: 46184 | S29: PAGADA
A30: Mayo | B30: 2026 | C30: 1007145275 | D30: CASTILLO RAMOS LESLI JHOJARA | E30: INCAPACIDAD GENERAL | F30: 46142 | G30: 46145 | H30: 4 | I30: NUEVA EPS | J30: 2489061 | K30: SI | L30: 46173 | N30: 1750905 | O30: 2 | P30: 116727
A31: Mayo | B31: 2026 | C31: 1152697576 | D31: CASTAÑEDA ROJAS YADILTHON FABIAN | E31: INCAPACIDAD GENERAL | F31: 46142 | G31: 46144 | H31: 3 | I31: NUEVA EPS | J31: 2489062 | K31: SI | L31: 46173 | N31: 1750905 | O31: 1 | P31: 58363.5 | Q31: 58364 | R31: 46255
A32: Mayo | B32: 2026 | C32: 1127579827 | D32: RAMIREZ BERRIO SUGEIDIS ANA MARIA | E32: INCAPACIDAD GENERAL | F32: 46157 | G32: 46159 | H32: 3 | I32: NUEVA EPS | J32: 2489064 | K32: SI | L32: 46173 | N32: 1750905 | O32: 1 | P32: 58363.5
A33: Mayo | B33: 2026 | C33: 1126904211 | D33: ORTIZ GONZALEZ WILMER EDUARDO | E33: INCAPACIDAD ACC LABORAL | F33: 46166 | G33: 46167 | H33: 2 | I33: ARL SURA | J33: 156219407001 | K33: SI | L33: 46173 | N33: 1750905 | O33: 2 | P33: 116727
A34: Mayo | B34: 2026 | C34: 1077429561 | D34: TORRES SANCHEZ YUNNIA YENSIER. | E34: INCAPACIDAD GENERAL | F34: 46154 | G34: 46183 | H34: 30 | I34: NUEVA EPS | J34: 2489065 | K34: SI | L34: 46173 | N34: 1750905 | O34: 28 | P34: 1634178 | Q34: 1634178 | R34: 46255
A35: Mayo | B35: 2026 | C35: 1053873691 | D35: RODRIGUEZ HERNANDEZ LULY GABRIELA | E35: INCAPACIDAD GENERAL | F35: 46142 | G35: 46144 | H35: 3 | I35: NUEVA EPS | J35: 2489066 | K35: SI | L35: 46173 | N35: 1750905 | O35: 1 | P35: 58363.5 | Q35: 58364
A36: Mayo | B36: 2026 | C36: 1030527733 | D36: RODRIGUEZ GARCIA DANNA VALENTINA | E36: INCAPACIDAD GENERAL | F36: 46149 | G36: 46155 | H36: 7 | I36: RECAUDO SGP CAPITAL SALUD | J36: RADICADO POR CORREO | K36: SI | L36: 46173 | M36: prestaciones@capitalsalud.gov.co | N36: 1750905 | O36: 5 | P36: 291817.5
A37: Mayo | B37: 2026 | C37: 1030552225 | D37: RUIZ RODRIGUEZ NICOLE VANESSA | E37: INCAPACIDAD GENERAL | F37: 46152 | G37: 46156 | H37: 5 | I37: RECAUDO SGP CAPITAL SALUD | J37: RADICADO POR CORREO | K37: SI | L37: 46173 | M37: prestaciones@capitalsalud.gov.co | N37: 1750905 | O37: 3 | P37: 175090.5
A38: Mayo | B38: 2026 | C38: 1030552225 | D38: RUIZ RODRIGUEZ NICOLE VANESSA | E38: INCAPACIDAD GENERAL | F38: 46169 | G38: 46171 | H38: 3 | I38: RECAUDO SGP CAPITAL SALUD | J38: RADICADO POR CORREO | K38: SI | L38: 46173 | M38: prestaciones@capitalsalud.gov.co | N38: 1750905 | O38: 1 | P38: 58363.5
A39: Mayo | B39: 2026 | C39: 1125082534 | D39: CARMONA OROZCO VALENTINA. | E39: INCAPACIDAD GENERAL | F39: 46158 | G39: 46161 | H39: 4 | I39: SALUD TOTAL S.A ENTIDAD PROMOTORA DE SALUD | J39: 0531261469 | K39: SI | L39: 46173 | M39: Por medio de una PQR | N39: 1750905 | O39: 2 | P39: 116727
A40: Mayo | B40: 2026 | C40: 1001888870 | D40: OSPINA MERCADO MAYRA ALEJANDRA | E40: INCAPACIDAD GENERAL | F40: 46162 | G40: 46164 | H40: 3 | I40: SALUD TOTAL S.A ENTIDAD PROMOTORA DE SALUD | J40: 0531261478 | K40: SI | L40: 46173 | N40: 1750905 | O40: 1 | P40: 58363.5 | Q40: 58364 | R40: 46238 | S40: PAGADA
...

Sheet Depuración de Cartera
A1: Año | B1: Mes | C1: Administradoras de pensión | D1: Estado de cuenta | E1: Valor Correción | F1: Valor a Pagar | G1: Valor Devolución
C2: porvenir
A3: 2026 | B3: Agosto | C3: Proteccion | D3: 348865
C4: colpensiones
A10: Año | B10: Mes | C10: Cajas de compensación | D10: Estado de cuenta | E10: Valor Correción | F10: Valor a Pagar | G10: Valor Devolución
C11: comfama
C12: comfenalco
C13: Comfamiliar
C14: Comfelnaco de cali
C15: Cafam
C16: Comfamilar barranquilla
A18: Año | B18: Mes | C18: Administradora de Salud | D18: Estado de cuenta | E18: Valor Correción | F18: Valor a Pagar | G18: Valor Devolución
A19: 2026 | B19: Agosto | C19: Salud Total | D19: 35749934
A20: 2026 | B20: Agosto | C20: Nueva eps | D20: 7638185
A21: 2026 | B21: Agosto | C21: Eps Sura | D21: 440899
A22: 2026 | B22: Agosto | C22: Sanitas | D22: 152600
A24: Año | B24: Mes | C24: ARL | D24: Estado de cuenta | E24: Valor Correción | F24: Valor a Pagar | G24: Valor Devolución
A25: 2026 | B25: Agosto | C25: Arl sura | D25: 291000
