Workbook

Sheet FESTIVOS
A1: DIAS NO LABORALES RESTO DEL PAIS | D1: DIAS NO LABORALES BOGOTÁ
A2: (Columna C) Fechas | B2: (Columna D - Opcional) Nombre | D2: (Columna C) Fechas | E2: (Columna D - Opcional) Nombre
A3: 45964 | B3: DIA DE TODOS LOS SANTOS | D3: 45964 | E3: DIA DE TODOS LOS SANTOS
A4: 45978 | B4: INDEPENDENCIA DE CARTAGENA | D4: 45978 | E4: INDEPENDENCIA DE CARTAGENA
A5: 45999 | B5: Inmaculada Concepción | D5: 45999 | E5: Inmaculada Concepción
A6: 46016 | B6: Navidad | D6: 46016 | E6: Navidad
A7: 46023 | B7: Año Nuevo | D7: 46023 | E7: Año Nuevo
A8: 46034 | B8: Día de los Reyes Magos | D8: 46034 | E8: Día de los Reyes Magos
A9: 46104 | B9: Día de San José | D9: 46104 | E9: Día de San José
A10: 46114 | B10: Jueves Santo | D10: 46114 | E10: Jueves Santo
A11: 46115 | B11: Viernes Santo | D11: 46115 | E11: Viernes Santo
A12: 46143 | B12: Día del Trabajo | D12: 46143 | E12: Día del Trabajo
A13: 46160 | B13: Día de la Ascensión | D13: 46160 | E13: Día de la Ascensión
A14: 46181 | B14: Corpus Christi | D14: 46181 | E14: Corpus Christi
... A24: 46381 | B24: Navidad | D24: 46381 | E24: Navidad

Sheet MEDELLÍN-RIONEGRO
A1: NOMBRE NUEVO INGRESO | B1: CARGO | C1: ESTADO | D1: FECHA DE INGRESO | E1: SOLICITA | F1: FECHA DE SOLICITUD | G1: PUNTO | H1: PERSONA A QUIEN REEMPLAZARA | I1: POSICION CLAVES | J1: MOTIVO | K1: FECHA MAXIMA | L1: MES_INDICADOR_K | M1: ESTADO DEL INGRESO
A2: REY DAVID VALDERRAMA DIAZ | B2: AUXILIAR DE SERVICIO | C2: CONTRATADO | D2: 46015 | E2: ANGIE | F2: 45971 | G2: MAYORCA 2 | H2: BENITEZ GUERRERO YESMIN ADRIANA | K2: {=IF(OR($B2="",$F2=""),"",WORKDAY.INTL(IF(ISNUMBER($F2),$F2,FECHA.VALOR($F2)),IF(UPPER(TRIM($B2))="AUXILIAR DE COCINA",10,15),1,FESTIVOS!$A$3:$A$1000))} -> 45993 | L2: =IF($F3="","",DATE( YEAR(EDATE($F3,IF(DAY($F3)>=IF(UPPER(TRIM($B3))="AUXILIAR DE COCINA",17,11),1,0))), MONTH(EDATE($F3,IF(DAY($F3)>=IF(UPPER(TRIM($B3))="AUXILIAR DE COCINA",17,11),1,0))), 1 )) -> 45992 | M2: =IF($K2="","",IF(OR($D2="",$D2<$F2),"PENDIENTE",IF($D2<=$K2,"A TIEMPO","FUERA DE TIEMPO"))) -> FUERA DE TIEMPO | O2: Cuenta de FECHA MAXIMA | Q2: ESTADO DEL INGRESO
A3: MARISOL ECHEVERRY GARCIA | B3: AUXILIAR DE SERVICIO | C3: CONTRATADO | D3: 45975 | E3: ANGIE | F3: 45972 | G3: VEGAS PLAZA | H3: ENMANUEL TUBERQUIA PEREZ | K3: {=IF(OR($B3="",$F3=""),"",WORKDAY.INTL(IF(ISNUMBER($F3),$F3,FECHA.VALOR($F3)),IF(UPPER(TRIM($B3))="AUXILIAR DE COCINA",10,15),1,FESTIVOS!$A$3:$A$1000))} -> 45994 | L3: =IF($F4="","",DATE( YEAR(EDATE($F4,IF(DAY($F4)>=IF(UPPER(TRIM($B4))="AUXILIAR DE COCINA",17,11),1,0))), MONTH(EDATE($F4,IF(DAY($F4)>=IF(UPPER(TRIM($B4))="AUXILIAR DE COCINA",17,11),1,0))), 1 )) -> 45992 | M3: =IF($K3="","",IF(OR($D3="",$D3<$F3),"PENDIENTE",IF($D3<=$K3,"A TIEMPO","FUERA DE TIEMPO"))) -> A TIEMPO | O3: MES_INDICADOR_K | P3: CARGO | Q3: A TIEMPO | R3: FUERA DE TIEMPO | S3: PENDIENTE | T3: #¡REF! | U3: Total general
A4: DINA LUZ PEÑA | B4: AUXILIAR DE COCINA | C4: CONTRATADO | D4: 45972 | E4: ANGIE | F4: 45979 | G4: PUERTA DEL NORTE | H4: MARIA ALEJANDRA ALMANZA RAMIREZ | K4: {=IF(OR($B4="",$F4=""),"",WORKDAY.INTL(IF(ISNUMBER($F4),$F4,FECHA.VALOR($F4)),IF(UPPER(TRIM($B4))="AUXILIAR DE COCINA",10,15),1,FESTIVOS!$A$3:$A$1000))} -> 45993 | L4: =IF($F5="","",DATE( YEAR(EDATE($F5,IF(DAY($F5)>=IF(UPPER(TRIM($B5))="AUXILIAR DE COCINA",17,11),1,0))), MONTH(EDATE($F5,IF(DAY($F5)>=IF(UPPER(TRIM($B5))="AUXILIAR DE COCINA",17,11),1,0))), 1 )) -> 45992 | M4: =IF($K4="","",IF(OR($D4="",$D4<$F4),"PENDIENTE",IF($D4<=$K4,"A TIEMPO","FUERA DE TIEMPO"))) -> PENDIENTE | P4: AUXILIAR DE COCINA | S4: 1 | U4: 1
A5: JULIAN ANDRES VALENCIA | B5: AUXILIAR DE COCINA | C5: CONTRATADO | D5: 45983 | E5: ANGIE | F5: 45979 | G5: ENVIGADO | H5: JUAN SEBASTIAN CELIS BLANDON | K5: {=IF(OR($B5="",$F5=""),"",WORKDAY.INTL(IF(ISNUMBER($F5),$F5,FECHA.VALOR($F5)),IF(UPPER(TRIM($B5))="AUXILIAR DE COCINA",10,15),1,FESTIVOS!$A$3:$A$1000))} -> 45993 | L5: =IF($F6="","",DATE( YEAR(EDATE($F6,IF(DAY($F6)>=IF(UPPER(TRIM($B6))="AUXILIAR DE COCINA",17,11),1,0))), MONTH(EDATE($F6,IF(DAY($F6)>=IF(UPPER(TRIM($B6))="AUXILIAR DE COCINA",17,11),1,0))), 1 )) -> 45992 | M5: =IF($K5="","",IF(OR($D5="",$D5<$F5),"PENDIENTE",IF($D5<=$K5,"A TIEMPO","FUERA DE TIEMPO"))) -> A TIEMPO | O5: Total | S5: 1 | U5: 1
A6: MIGUEL ANGEL CASTAÑO | B6: AUXILIAR DE COCINA | C6: CONTRATADO | D6: 45983 | E6: ANGIE | F6: 45979 | G6: SUPERNUEMRARIA | H6: YERIKA BIBIANA ARIAS VASQUEZ | K6: {=IF(OR($B6="",$F6=""),"",WORKDAY.INTL(IF(ISNUMBER($F6),$F6,FECHA.VALOR($F6)),IF(UPPER(TRIM($B6))="AUXILIAR DE COCINA",10,15),1,FESTIVOS!$A$3:$A$1000))} -> 45993 | L6: =IF($F7="","",DATE( YEAR(EDATE($F7,IF(DAY($F7)>=IF(UPPER(TRIM($B7))="AUXILIAR DE COCINA",17,11),1,0))), MONTH(EDATE($F7,IF(DAY($F7)>=IF(UPPER(TRIM($B7))="AUXILIAR DE COCINA",17,11),1,0))), 1 )) -> 45992 | M6: =IF($K6="","",IF(OR($D6="",$D6<$F6),"PENDIENTE",IF($D6<=$K6,"A TIEMPO","FUERA DE TIEMPO"))) -> A TIEMPO | O6: #¡REF! | P6: AUXILIAR DE COCINA | Q6: 1 | U6: 1
A7: PAULA ANDREA MOSQUERA | B7: AUXILIAR DE COCINA | C7: CONTRATADO | D7: 45983 | E7: ANGIE | F7: 45979 | G7: DISTRITO VERA | H7: ALEXANDER MACHADO OSORIO | K7: {=IF(OR($B7="",$F7=""),"",WORKDAY.INTL(IF(ISNUMBER($F7),$F7,FECHA.VALOR($F7)),IF(UPPER(TRIM($B7))="AUXILIAR DE COCINA",10,15),1,FESTIVOS!$A$3:$A$1000))} -> 45993 | L7: =IF($F8="","",DATE( YEAR(EDATE($F8,IF(DAY($F8)>=IF(UPPER(TRIM($B8))="AUXILIAR DE COCINA",17,11),1,0))), MONTH(EDATE($F8,IF(DAY($F8)>=IF(UPPER(TRIM($B8))="AUXILIAR DE COCINA",17,11),1,0))), 1 )) -> 45992 | M7: =IF($K7="","",IF(OR($D7="",$D7<$F7),"PENDIENTE",IF($D7<=$K7,"A TIEMPO","FUERA DE TIEMPO"))) -> A TIEMPO | P7: AUXILIAR DE SERVICIO | R7: 1 | U7: 1
A8: PAULA ANDREA RAMIREZ | B8: AUXILIAR DE COCINA | C8: CONTRATADO | D8: 45983 | E8: ANGIE | F8: 45979 | G8: SUPERNUMERARIO | H8: JENNY JOHANA RENGIFO JARAMILLO | K8: {=IF(OR($B8="",$F8=""),"",WORKDAY.INTL(IF(ISNUMBER($F8),$F8,FECHA.VALOR($F8)),IF(UPPER(TRIM($B8))="AUXILIAR DE COCINA",10,15),1,FESTIVOS!$A$3:$A$1000))} -> 45993 | L8: =IF($F9="","",DATE( YEAR(EDATE($F9,IF(DAY($F9)>=IF(UPPER(TRIM($B9))="AUXILIAR DE COCINA",17,11),1,0))), MONTH(EDATE($F9,IF(DAY($F9)>=IF(UPPER(TRIM($B9))="AUXILIAR DE COCINA",17,11),1,0))), 1 )) -> 45992 | M8: =IF($K8="","",IF(OR($D8="",$D8<$F8),"PENDIENTE",IF($D8<=$K8,"A TIEMPO","FUERA DE TIEMPO"))) -> A TIEMPO | O8: Total #¡REF! | Q8: 1 | R8: 1 | U8: 2
A9: KAREN YANETH ANAYA | B9: AUXILIAR DE COCINA | C9: CONTRATADO | D9: 45987 | E9: ANGIE | F9: 45979 | G9: DISTRITO VERA | H9: SEBASTIAN SANCHEZ MARIN | K9: {=IF(OR($B9="",$F9=""),"",WORKDAY.INTL(IF(ISNUMBER($F9),$F9,FECHA.VALOR($F9)),IF(UPPER(TRIM($B9))="AUXILIAR DE COCINA",10,15),1,FESTIVOS!$A$3:$A$1000))} -> 45993 | L9: =IF($F10="","",DATE( YEAR(EDATE($F10,IF(DAY($F10)>=IF(UPPER(TRIM($B10))="AUXILIAR DE COCINA",17,11),1,0))), MONTH(EDATE($F10,IF(DAY($F10)>=IF(UPPER(TRIM($B10))="AUXILIAR DE COCINA",17,11),1,0))), 1 )) -> 45992 | M9: =IF($K9="","",IF(OR($D9="",$D9<$F9),"PENDIENTE",IF($D9<=$K9,"A TIEMPO","FUERA DE TIEMPO"))) -> A TIEMPO | O9: 45992 | P9: AUXILIAR DE COCINA | Q9: 24 | R9: 5 | S9: 1 | U9: 30
A10: NELLIS JUDITH GAMEZ LOPEZ | B10: AUXILIAR DE COCINA | C10: CONTRATADO | D10: 45989 | E10: ANGIE | F10: 45979 | G10: SUPERNUEMRARIA | H10: LUISA FERNANDA AGUDELO CEBALLOS | K10: {=IF(OR($B10="",$F10=""),"",WORKDAY.INTL(IF(ISNUMBER($F10),$F10,FECHA.VALOR($F10)),IF(UPPER(TRIM($B10))="AUXILIAR DE COCINA",10,15),1,FESTIVOS!$A$3:$A$1000))} -> 45993 | L10: =IF($F11="","",DATE( YEAR(EDATE($F11,IF(DAY($F11)>=IF(UPPER(TRIM($B11))="AUXILIAR DE COCINA",17,11),1,0))), MONTH(EDATE($F11,IF(DAY($F11)>=IF(UPPER(TRIM($B11))="AUXILIAR DE COCINA",17,11),1,0))), 1 )) -> 45992 | M10: =IF($K10="","",IF(OR($D10="",$D10<$F10),"PENDIENTE",IF($D10<=$K10,"A TIEMPO","FUERA DE TIEMPO"))) -> A TIEMPO | P10: AUXILIAR DE SERVICIO | Q10: 6 | R10: 2 | U10: 8
A11: PAULA ANDREA LONDOÑO GUERRERO | B11: AUXILIAR DE COCINA | C11: CONTRATADO | D11: 45989 | E11: ANGIE | F11: 45979 | G11: SUPERNUMERARIO | H11: LUIS CARLOS CUADRADO MORA | K11: {=IF(OR($B11="",$F11=""),"",WORKDAY.INTL(IF(ISNUMBER($F11),$F11,FECHA.VALOR($F11)),IF(UPPER(TRIM($B11))="AUXILIAR DE COCINA",10,15),1,FESTIVOS!$A$3:$A$1000))} -> 45993 | L11: =IF($F12="","",DATE( YEAR(EDATE($F12,IF(DAY($F12)>=IF(UPPER(TRIM($B12))="AUXILIAR DE COCINA",17,11),1,0))), MONTH(EDATE($F12,IF(DAY($F12)>=IF(UPPER(TRIM($B12))="AUXILIAR DE COCINA",17,11),1,0))), 1 )) -> 45992 | M11: =IF($K11="","",IF(OR($D11="",$D11<$F11),"PENDIENTE",IF($D11<=$K11,"A TIEMPO","FUERA DE TIEMPO"))) -> A TIEMPO | O11: Total 01/12/2025 | Q11: 30 | R11: 7 | S11: 1 | U11: 38
A12: DEILER RAMIREZ MENDOSA | B12: AUXILIAR DE COCINA | C12: CONTRATADO | D12: 45993 | E12: ANGIE | F12: 45979 | G12: OVIEDO | H12: BRANDIS LUZ BELLO BLANCO | K12: {=IF(OR($B12="",$F12=""),"",WORKDAY.INTL(IF(ISNUMBER($F12),$F12,FECHA.VALOR($F12)),IF(UPPER(TRIM($B12))="AUXILIAR DE COCINA",10,15),1,FESTIVOS!$A$3:$A$1000))} -> 45993 | L12: =IF($F13="","",DATE( YEAR(EDATE($F13,IF(DAY($F13)>=IF(UPPER(TRIM($B13))="AUXILIAR DE COCINA",17,11),1,0))), MONTH(EDATE($F13,IF(DAY($F13)>=IF(UPPER(TRIM($B13))="AUXILIAR DE COCINA",17,11),1,0))), 1 )) -> 45992 | M12: =IF($K12="","",IF(OR($D12="",$D12<$F12),"PENDIENTE",IF($D12<=$K12,"A TIEMPO","FUERA DE TIEMPO"))) -> A TIEMPO | O12: 46023 | P12: AUXILIAR DE COCINA | Q12: 16 | R12: 2 | T12: 2 | U12: 20
A13: EMILCE ISABEL HERNANDEZ | B13: AUXILIAR DE SERVICIO | C13: CONTRATADO | D13: 45987 | E13: ANGIE | F13: 45979 | H13: VALENCIA PROAÑOS JENNY ALEJANDRA | K13: {=IF(OR($B13="",$F13=""),"",WORKDAY.INTL(IF(ISNUMBER($F13),$F13,FECHA.VALOR($F13)),IF(UPPER(TRIM($B13))="AUXILIAR DE COCINA",10,15),1,FESTIVOS!$A$3:$A$1000))} -> 46001 | L13: =IF($F14="","",DATE( YEAR(EDATE($F14,IF(DAY($F14)>=IF(UPPER(TRIM($B14))="AUXILIAR DE COCINA",17,11),1,0))), MONTH(EDATE($F14,IF(DAY($F14)>=IF(UPPER(TRIM($B14))="AUXILIAR DE COCINA",17,11),1,0))), 1 )) -> 45992 | M13: =IF($K13="","",IF(OR($D13="",$D13<$F13),"PENDIENTE",IF($D13<=$K13,"A TIEMPO","FUERA DE TIEMPO"))) -> A TIEMPO | P13: AUXILIAR DE SERVICIO | Q13: 3 | S13: 1 | U13: 4
A14: MARIO ANDRES MAIGUAL COGOLLO | B14: AUXILIAR DE COCINA | C14: CONTRATADO | D14: 45995 | E14: ANGIE | F14: 45981 | G14: FLORIDA 1 | H14: MARCELA YULIETH MARTINEZ BLANDON | K14: {=IF(OR($B14="",$F14=""),"",WORKDAY.INTL(IF(ISNUMBER($F14),$F14,FECHA.VALOR($F14)),IF(UPPER(TRIM($B14))="AUXILIAR DE COCINA",10,15),1,FESTIVOS!$A$3:$A$1000))} -> 45995 | L14: =IF($F15="","",DATE( YEAR(EDATE($F15,IF(DAY($F15)>=IF(UPPER(TRIM($B15))="AUXILIAR DE COCINA",17,11),1,0))), MONTH(EDATE($F15,IF(DAY($F15)>=IF(UPPER(TRIM($B15))="AUXILIAR DE COCINA",17,11),1,0))), 1 )) -> 45992 | M14: =IF($K14="","",IF(OR($D14="",$D14<$F14),"PENDIENTE",IF($D14<=$K14,"A TIEMPO","FUERA DE TIEMPO"))) -> A TIEMPO | O14: Total 01/01/2026 | Q14: 19 | R14: 2 | S14: 1 | T14: 2 | U14: 24
A15: MONICA MARCELA MONTOYA CAÑAS | B15: AUXILIAR DE COCINA | C15: CONTRATADO | D15: 45995 | E15: ANGIE | F15: 45981 | G15: SANTA FE | H15: HERNANDEZ ANGULO NAUDITH | K15: {=IF(OR($B15="",$F15=""),"",WORKDAY.INTL(IF(ISNUMBER($F15),$F15,FECHA.VALOR($F15)),IF(UPPER(TRIM($B15))="AUXILIAR DE COCINA",10,15),1,FESTIVOS!$A$3:$A$1000))} -> 45995 | L15: =IF($F16="","",DATE( YEAR(EDATE($F16,IF(DAY($F16)>=IF(UPPER(TRIM($B16))="AUXILIAR DE COCINA",17,11),1,0))), MONTH(EDATE($F16,IF(DAY($F16)>=IF(UPPER(TRIM($B16))="AUXILIAR DE COCINA",17,11),1,0))), 1 )) -> 45992 | M15: =IF($K15="","",IF(OR($D15="",$D15<$F15),"PENDIENTE",IF($D15<=$K15,"A TIEMPO","FUERA DE TIEMPO"))) -> A TIEMPO | O15: 46054 | P15: AUXILIAR DE COCINA | Q15: 2 | S15: 11 | U15: 13
A16: CINDI MILENA MARTINEZ IBARGUEN | B16: AUXILIAR DE COCINA | C16: CONTRATADO | D16: 45994 | E16: ANGIE | F16: 45982 | G16: LA CENTRAL | H16: JUAN ESTEBAN RIOS PALACIO | K16: {=IF(OR($B16="",$F16=""),"",WORKDAY.INTL(IF(ISNUMBER($F16),$F16,FECHA.VALOR($F16)),IF(UPPER(TRIM($B16))="AUXILIAR DE COCINA",10,15),1,FESTIVOS!$A$3:$A$1000))} -> 45996 | L16: =IF($F17="","",DATE( YEAR(EDATE($F17,IF(DAY($F17)>=IF(UPPER(TRIM($B17))="AUXILIAR DE COCINA",17,11),1,0))), MONTH(EDATE($F17,IF(DAY($F17)>=IF(UPPER(TRIM($B17))="AUXILIAR DE COCINA",17,11),1,0))), 1 )) -> 45992 | M16: =IF($K16="","",IF(OR($D16="",$D16<$F16),"PENDIENTE",IF($D16<=$K16,"A TIEMPO","FUERA DE TIEMPO"))) -> A TIEMPO | P16: AUXILIAR DE SERVICIO | Q16: 1 | U16: 1
A17: NATALIA ANDREA HOLGUIN | B17: AUXILIAR DE COCINA | C17: CONTRATADO | D17: 45994 | E17: ANGIE | F17: 45982 | G17: OVIEDO | H17: NORLIDIS LLORENTE | K17: {=IF(OR($B17="",$F17=""),"",WORKDAY.INTL(IF(ISNUMBER($F17),$F17,FECHA.VALOR($F17)),IF(UPPER(TRIM($B17))="AUXILIAR DE COCINA",10,15),1,FESTIVOS!$A$3:$A$1000))} -> 45996 | L17: =IF($F18="","",DATE( YEAR(EDATE($F18,IF(DAY($F18)>=IF(UPPER(TRIM($B18))="AUXILIAR DE COCINA",17,11),1,0))), MONTH(EDATE($F18,IF(DAY($F18)>=IF(UPPER(TRIM($B18))="AUXILIAR DE COCINA",17,11),1,0))), 1 )) -> 45992 | M17: =IF($K17="","",IF(OR($D17="",$D17<$F17),"PENDIENTE",IF($D17<=$K17,"A TIEMPO","FUERA DE TIEMPO"))) -> A TIEMPO | O17: Total 01/02/2026 | Q17: 3 | S17: 11 | U17: 14
A18: JULIAN DAVID POLO BARRIOS | B18: AUXILIAR DE COCINA | C18: CONTRATADO | D18: 46007 | E18: ANGIE | F18: 45982 | G18: FLORIDA 2 | H18: NUÑES HORTA MARIA JOSE | K18: {=IF(OR($B18="",$F18=""),"",WORKDAY.INTL(IF(ISNUMBER($F18),$F18,FECHA.VALOR($F18)),IF(UPPER(TRIM($B18))="AUXILIAR DE COCINA",10,15),1,FESTIVOS!$A$3:$A$1000))} -> 45996 | L18: =IF($F19="","",DATE( YEAR(EDATE($F19,IF(DAY($F19)>=IF(UPPER(TRIM($B19))="AUXILIAR DE COCINA",17,11),1,0))), MONTH(EDATE($F19,IF(DAY($F19)>=IF(UPPER(TRIM($B19))="AUXILIAR DE COCINA",17,11),1,0))), 1 )) -> 45992 | M18: =IF($K18="","",IF(OR($D18="",$D18<$F18),"PENDIENTE",IF($D18<=$K18,"A TIEMPO","FUERA DE TIEMPO"))) -> FUERA DE TIEMPO | O18: Total general | Q18: 53 | R18: 10 | S18: 14 | T18: 2 | U18: 79
A19: EMILCE ISABEL HERNANDEZ | B19: AUXILIAR DE SERVICIO | C19: CONTRATADO | D19: 45987 | E19: ANGIE | F19: 45985 | H19: VALENCIA PROAÑOS JENNY ALEJANDRA | K19: {=IF(OR($B19="",$F19=""),"",WORKDAY.INTL(IF(ISNUMBER($F19),$F19,FECHA.VALOR($F19)),IF(UPPER(TRIM($B19))="AUXILIAR DE COCINA",10,15),1,FESTIVOS!$A$3:$A$1000))} -> 46007 | L19: =IF($F20="","",DATE( YEAR(EDATE($F20,IF(DAY($F20)>=IF(UPPER(TRIM($B20))="AUXILIAR DE COCINA",17,11),1,0))), MONTH(EDATE($F20,IF(DAY($F20)>=IF(UPPER(TRIM($B20))="AUXILIAR DE COCINA",17,11),1,0))), 1 )) -> 45992 | M19: =IF($K19="","",IF(OR($D19="",$D19<$F19),"PENDIENTE",IF($D19<=$K19,"A TIEMPO","FUERA DE TIEMPO"))) -> A TIEMPO
A20: ELIANA ESTRADA SUAREZ | B20: AUXILIAR DE SERVICIO | C20: CONTRATADO | D20: 46007 | E20: ANGIE | F20: 45985 | G20: SUPERNUMERARIO | H20: SINDY PATRICIA MELENDRES SALGADO | K20: {=IF(OR($B20="",$F20=""),"",WORKDAY.INTL(IF(ISNUMBER($F20),$F20,FECHA.VALOR($F20)),IF(UPPER(TRIM($B20))="AUXILIAR DE COCINA",10,15),1,FESTIVOS!$A$3:$A$1000))} -> 46007 | L20: =IF($F21="","",DATE( YEAR(EDATE($F21,IF(DAY($F21)>=IF(UPPER(TRIM($B21))="AUXILIAR DE COCINA",17,11),1,0))), MONTH(EDATE($F21,IF(DAY($F21)>=IF(UPPER(TRIM($B21))="AUXILIAR DE COCINA",17,11),1,0))), 1 )) -> 45992 | M20: =IF($K20="","",IF(OR($D20="",$D20<$F20),"PENDIENTE",IF($D20<=$K20,"A TIEMPO","FUERA DE TIEMPO"))) -> A TIEMPO
A21: YEINIS GRACIALA GUTIERREZ | B21: AUXILIAR DE SERVICIO | C21: CONTRATADO | D21: 46007 | E21: ANGIE | F21: 45986 | G21: VIVA LAURELES | H21: VALDERRAMA ORTEGA KEVIN | K21: {=IF(OR($B21="",$F21=""),"",WORKDAY.INTL(IF(ISNUMBER($F21),$F21,FECHA.VALOR($F21)),IF(UPPER(TRIM($B21))="AUXILIAR DE COCINA",10,15),1,FESTIVOS!$A$3:$A$1000))} -> 46008 | L21: =IF($F22="","",DATE( YEAR(EDATE($F22,IF(DAY($F22)>=IF(UPPER(TRIM($B22))="AUXILIAR DE COCINA",17,11),1,0))), MONTH(EDATE($F22,IF(DAY($F22)>=IF(UPPER(TRIM($B22))="AUXILIAR DE COCINA",17,11),1,0))), 1 )) -> 45992 | M21: =IF($K21="","",IF(OR($D21="",$D21<$F21),"PENDIENTE",IF($D21<=$K21,"A TIEMPO","FUERA DE TIEMPO"))) -> A TIEMPO
A22: ANGELA CÉCILIA ÁLVAREZ | B22: AUXILIAR DE SERVICIO | C22: CONTRATADO | D22: 46007 | E22: ANGIE | F22: 45986 | G22: LA CENTRAL | H22: JULIAN ANDRES VALENCIA OCAMPO | K22: {=IF(OR($B22="",$F22=""),"",WORKDAY.INTL(IF(ISNUMBER($F22),$F22,FECHA.VALOR($F22)),IF(UPPER(TRIM($B22))="AUXILIAR DE COCINA",10,15),1,FESTIVOS!$A$3:$A$1000))} -> 46008 | L22: =IF($F23="","",DATE( YEAR(EDATE($F23,IF(DAY($F23)>=IF(UPPER(TRIM($B23))="AUXILIAR DE COCINA",17,11),1,0))), MONTH(EDATE($F23,IF(DAY($F23)>=IF(UPPER(TRIM($B23))="AUXILIAR DE COCINA",17,11),1,0))), 1 )) -> 45992 | M22: =IF($K22="","",IF(OR($D22="",$D22<$F22),"PENDIENTE",IF($D22<=$K22,"A TIEMPO","FUERA DE TIEMPO"))) -> A TIEMPO
A23: DERWIN PAJARO MEDINA | B23: AUXILIAR DE SERVICIO | C23: CONTRATADO | D23: 46041 | E23: ANGIE | F23: 45986 | G23: SANTA FE | H23: BERRIO GUEVARA MARIA ISABEL | K23: {=IF(OR($B23="",$F23=""),"",WORKDAY.INTL(IF(ISNUMBER($F23),$F23,FECHA.VALOR($F23)),IF(UPPER(TRIM($B23))="AUXILIAR DE COCINA",10,15),1,FESTIVOS!$A$3:$A$1000))} -> 46008 | L23: =IF($F24="","",DATE( YEAR(EDATE($F24,IF(DAY($F24)>=IF(UPPER(TRIM($B24))="AUXILIAR DE COCINA",17,11),1,0))), MONTH(EDATE($F24,IF(DAY($F24)>=IF(UPPER(TRIM($B24))="AUXILIAR DE COCINA",17,11),1,0))), 1 )) -> 45992 | M23: =IF($K23="","",IF(OR($D23="",$D23<$F23),"PENDIENTE",IF($D23<=$K23,"A TIEMPO","FUERA DE TIEMPO"))) -> FUERA DE TIEMPO
A24: KAREN DALLANA LARGACHA | B24: AUXILIAR DE COCINA | C24: CONTRATADO | D24: 46008 | E24: ANGIE | F24: 45993 | G24: SUPERNUMERARIO | H24: ORREGO CALLE LAURA | K24: {=IF(OR($B24="",$F24=""),"",WORKDAY.INTL(IF(ISNUMBER($F24),$F24,FECHA.VALOR($F24)),IF(UPPER(TRIM($B24))="AUXILIAR DE COCINA",10,15),1,FESTIVOS!$A$3:$A$1000))} -> 46008 | L24: =IF($F25="","",DATE( YEAR(EDATE($F25,IF(DAY($F25)>=IF(UPPER(TRIM($B25))="AUXILIAR DE COCINA",17,11),1,0))), MONTH(EDATE($F25,IF(DAY($F25)>=IF(UPPER(TRIM($B25))="AUXILIAR DE COCINA",17,11),1,0))), 1 )) -> 45992 | M24: =IF($K24="","",IF(OR($D24="",$D24<$F24),"PENDIENTE",IF($D24<=$K24,"A TIEMPO","FUERA DE TIEMPO"))) -> A TIEMPO
A25: LUISA FERNANDA PELUFO | B25: AUXILIAR DE COCINA | C25: CONTRATADO | D25: 46007 | E25: ANGIE | F25: 45994 | G25: VIVA ENVIGADO | H25: PEREZ BERRIO LEIDIS | K25: {=IF(OR($B25="",$F25=""),"",WORKDAY.INTL(IF(ISNUMBER($F25),$F25,FECHA.VALOR($F25)),IF(UPPER(TRIM($B25))="AUXILIAR DE COCINA",10,15),1,FESTIVOS!$A$3:$A$1000))} -> 46009 | L25: =IF($F26="","",DATE( YEAR(EDATE($F26,IF(DAY($F26)>=IF(UPPER(TRIM($B26))="AUXILIAR DE COCINA",17,11),1,0))), MONTH(EDATE($F26,IF(DAY($F26)>=IF(UPPER(TRIM($B26))="AUXILIAR DE COCINA",17,11),1,0))), 1 )) -> 45992 | M25: =IF($K25="","",IF(OR($D25="",$D25<$F25),"PENDIENTE",IF($D25<=$K25,"A TIEMPO","FUERA DE TIEMPO"))) -> A TIEMPO
A26: LEIDY BIVIANA GALVIS | B26: AUXILIAR DE COCINA | C26: CONTRATADO | D26: 46008 | E26: ANGIE | F26: 45994 | G26: ARKADIA | H26: OCHOA SANCHEZ MARIANA | K26: {=IF(OR($B26="",$F26=""),"",WORKDAY.INTL(IF(ISNUMBER($F26),$F26,FECHA.VALOR($F26)),IF(UPPER(TRIM($B26))="AUXILIAR DE COCINA",10,15),1,FESTIVOS!$A$3:$A$1000))} -> 46009 | L26: =IF($F27="","",DATE( YEAR(EDATE($F27,IF(DAY($F27)>=IF(UPPER(TRIM($B27))="AUXILIAR DE COCINA",17,11),1,0))), MONTH(EDATE($F27,IF(DAY($F27)>=IF(UPPER(TRIM($B27))="AUXILIAR DE COCINA",17,11),1,0))), 1 )) -> 45992 | M26: =IF($K26="","",IF(OR($D26="",$D26<$F26),"PENDIENTE",IF($D26<=$K26,"A TIEMPO","FUERA DE TIEMPO"))) -> A TIEMPO
A27: LAURA ECHAVARRIA | B27: AUXILIAR DE COCINA | C27: CONTRATADO | D27: 46008 | E27: ANGIE | F27: 45994 | G27: GRAN PLAZA | H27: CHANCI NAVARRO YULIETH PAOLA | I27: 0 | K27: {=IF(OR($B27="",$F27=""),"",WORKDAY.INTL(IF(ISNUMBER($F27),$F27,FECHA.VALOR($F27)),IF(UPPER(TRIM($B27))="AUXILIAR DE COCINA",10,15),1,FESTIVOS!$A$3:$A$1000))} -> 46009 | L27: =IF($F28="","",DATE( YEAR(EDATE($F28,IF(DAY($F28)>=IF(UPPER(TRIM($B28))="AUXILIAR DE COCINA",17,11),1,0))), MONTH(EDATE($F28,IF(DAY($F28)>=IF(UPPER(TRIM($B28))="AUXILIAR DE COCINA",17,11),1,0))), 1 )) -> 45992 | M27: =IF($K27="","",IF(OR($D27="",$D27<$F27),"PENDIENTE",IF($D27<=$K27,"A TIEMPO","FUERA DE TIEMPO"))) -> A TIEMPO
A28: SACRA ISABEL COCHERO | B28: AUXILIAR DE COCINA | C28: CONTRATADO | D28: 46008 | E28: ANGIE | F28: 45994 | G28: VIVA ENVIGADO | H28: ROHIMER RAMON RONDON | K28: {=IF(OR($B28="",$F28=""),"",WORKDAY.INTL(IF(ISNUMBER($F28),$F28,FECHA.VALOR($F28)),IF(UPPER(TRIM($B28))="AUXILIAR DE COCINA",10,15),1,FESTIVOS!$A$3:$A$1000))} -> 46009 | L28: =IF($F29="","",DATE( YEAR(EDATE($F29,IF(DAY($F29)>=IF(UPPER(TRIM($B29))="AUXILIAR DE COCINA",17,11),1,0))), MONTH(EDATE($F29,IF(DAY($F29)>=IF(UPPER(TRIM($B29))="AUXILIAR DE COCINA",17,11),1,0))), 1 )) -> 45992 | M28: =IF($K28="","",IF(OR($D28="",$D28<$F28),"PENDIENTE",IF($D28<=$K28,"A TIEMPO","FUERA DE TIEMPO"))) -> A TIEMPO
A29: MARIA ANA CIRIA PLACIOS | B29: AUXILIAR DE COCINA | C29: CONTRATADO | D29: 46010 | E29: ANGIE | F29: 45994 | G29: MAYORCA 1 | H29: GARCÍA CADAVID MATEO SMIT | K29: 46015 | L29: =IF($F30="","",DATE( YEAR(EDATE($F30,IF(DAY($F30)>=IF(UPPER(TRIM($B30))="AUXILIAR DE COCINA",17,11),1,0))), MONTH(EDATE($F30,IF(DAY($F30)>=IF(UPPER(TRIM($B30))="AUXILIAR DE COCINA",17,11),1,0))), 1 )) -> 45992 | M29: =IF($K29="","",IF(OR($D29="",$D29<$F29),"PENDIENTE",IF($D29<=$K29,"A TIEMPO","FUERA DE TIEMPO"))) -> A TIEMPO
A30: SARA GUTIERREZ | B30: AUXILIAR DE COCINA | C30: CONTRATADO | D30: 46010 | E30: ANGIE | F30: 45994 | G30: OVIEDO | H30: PEDROZO ZANBRANO RICARDO | K30: 46015 | L30: =IF($F31="","",DATE( YEAR(EDATE($F31,IF(DAY($F31)>=IF(UPPER(TRIM($B31))="AUXILIAR DE COCINA",17,11),1,0))), MONTH(EDATE($F31,IF(DAY($F31)>=IF(UPPER(TRIM($B31))="AUXILIAR DE COCINA",17,11),1,0))), 1 )) -> 45992 | M30: =IF($K30="","",IF(OR($D30="",$D30<$F30),"PENDIENTE",IF($D30<=$K30,"A TIEMPO","FUERA DE TIEMPO"))) -> A TIEMPO
A31: DRAIDY YESELY MEJIA | B31: AUXILIAR DE COCINA | C31: CONTRATADO | D31: 46010 | E31: ANGIE | F31: 45994 | G31: OVIEDO | H31: FUENTES NARANJO NICK MICHELL | K31: 46015 | L31: =IF($F32="","",DATE( YEAR(EDATE($F32,IF(DAY($F32)>=IF(UPPER(TRIM($B32))="AUXILIAR DE COCINA",17,11),1,0))), MONTH(EDATE($F32,IF(DAY($F32)>=IF(UPPER(TRIM($B32))="AUXILIAR DE COCINA",17,11),1,0))), 1 )) -> 45992 | M31: =IF($K31="","",IF(OR($D31="",$D31<$F31),"PENDIENTE",IF($D31<=$K31,"A TIEMPO","FUERA DE TIEMPO"))) -> A TIEMPO
A32: YASITH LUZ HERRERA PEREZ | B32: AUXILIAR DE SERVICIO | C32: CONTRATADO | D32: 46024 | E32: ANGIE | F32: 45995 | G32: SUPERNUMERARIA | H32: CAROLINA LOPEZ ZAPATA | K32: {=IF(OR($B32="",$F32=""),"",WORKDAY.INTL(IF(ISNUMBER($F32),$F32,FECHA.VALOR($F32)),IF(UPPER(TRIM($B32))="AUXILIAR DE COCINA",10,15),1,FESTIVOS!$A$3:$A$1000))} -> 46020 | L32: =IF(#REF!="","",DATE( YEAR(EDATE(#REF!,IF(DAY(#REF!)>=IF(UPPER(TRIM(#REF!))="AUXILIAR DE COCINA",17,11),1,0))), MONTH(EDATE(#REF!,IF(DAY(#REF!)>=IF(UPPER(TRIM(#REF!))="AUXILIAR DE COCINA",17,11),1,0))), 1 )) -> #REF! | M32: =IF($K32="","",IF(OR($D32="",$D32<$F32),"PENDIENTE",IF($D32<=$K32,"A TIEMPO","FUERA DE TIEMPO"))) -> FUERA DE TIEMPO
A33: VALENTINA VANESSA GOMEZ | B33: AUXILIAR DE COCINA | C33: CONTRATADO | D33: 46010 | E33: ANGIE | F33: 45996 | G33: DE MODA | H33: BONILLA FERNANDEZ RICARDO ENMANUEL | K33: {=IF(OR($B33="",$F33=""),"",WORKDAY.INTL(IF(ISNUMBER($F33),$F33,FECHA.VALOR($F33)),IF(UPPER(TRIM($B33))="AUXILIAR DE COCINA",10,15),1,FESTIVOS!$A$3:$A$1000))} -> 46013 | L33: =IF($F34="","",DATE( YEAR(EDATE($F34,IF(DAY($F34)>=IF(UPPER(TRIM($B34))="AUXILIAR DE COCINA",17,11),1,0))), MONTH(EDATE($F34,IF(DAY($F34)>=IF(UPPER(TRIM($B34))="AUXILIAR DE COCINA",17,11),1,0))), 1 )) -> 45992 | M33: =IF($K33="","",IF(OR($D33="",$D33<$F33),"PENDIENTE",IF($D33<=$K33,"A TIEMPO","FUERA DE TIEMPO"))) -> A TIEMPO
A34: JOSE ANGEL MEZA | B34: AUXILIAR DE COCINA | C34: CONTRATADO | D34: 46010 | E34: ANGIE | F34: 45996 | G34: VIVA ENVIGADO | H34: DOGIRAMA MANYOMA JHOANA | K34: {=IF(OR($B34="",$F34=""),"",WORKDAY.INTL(IF(ISNUMBER($F34),$F34,FECHA.VALOR($F34)),IF(UPPER(TRIM($B34))="AUXILIAR DE COCINA",10,15),1,FESTIVOS!$A$3:$A$1000))} -> 46013 | L34: =IF($F35="","",DATE( YEAR(EDATE($F35,IF(DAY($F35)>=IF(UPPER(TRIM($B35))="AUXILIAR DE COCINA",17,11),1,0))), MONTH(EDATE($F35,IF(DAY($F35)>=IF(UPPER(TRIM($B35))="AUXILIAR DE COCINA",17,11),1,0))), 1 )) -> 45992 | M34: =IF($K34="","",IF(OR($D34="",$D34<$F34),"PENDIENTE",IF($D34<=$K34,"A TIEMPO","FUERA DE TIEMPO"))) -> A TIEMPO
A35: SARAI MARIA HERNANDEZ | B35: AUXILIAR DE COCINA | C35: CONTRATADO | D35: 46010 | E35: ANGIE | F35: 45996 | G35: SANTA FE | H35: SILGADO RUIZ LUISANA | K35: {=IF(OR($B35="",$F35=""),"",WORKDAY.INTL(IF(ISNUMBER($F35),$F35,FECHA.VALOR($F35)),IF(UPPER(TRIM($B35))="AUXILIAR DE COCINA",10,15),1,FESTIVOS!$A$3:$A$1000))} -> 46013 | L35: =IF($F36="","",DATE( YEAR(EDATE($F36,IF(DAY($F36)>=IF(UPPER(TRIM($B36))="AUXILIAR DE COCINA",17,11),1,0))), MONTH(EDATE($F36,IF(DAY($F36)>=IF(UPPER(TRIM($B36))="AUXILIAR DE COCINA",17,11),1,0))), 1 )) -> 45992 | M35: =IF($K35="","",IF(OR($D35="",$D35<$F35),"PENDIENTE",IF($D35<=$K35,"A TIEMPO","FUERA DE TIEMPO"))) -> A TIEMPO
A36: DIEGO ALONSO OCAMPO YEPES | B36: AUXILIAR DE COCINA | C36: CONTRATADO | D36: 46010 | E36: ANGIE | F36: 45999 | G36: DE MODA | H36: ORTEGA PALMA JANER RAFAEL | K36: {=IF(OR($B36="",$F36=""),"",WORKDAY.INTL(IF(ISNUMBER($F36),$F36,FECHA.VALOR($F36)),IF(UPPER(TRIM($B36))="AUXILIAR DE COCINA",10,15),1,FESTIVOS!$A$3:$A$1000))} -> 46013 | L36: =IF($F37="","",DATE( YEAR(EDATE($F37,IF(DAY($F37)>=IF(UPPER(TRIM($B37))="AUXILIAR DE COCINA",17,11),1,0))), MONTH(EDATE($F37,IF(DAY($F37)>=IF(UPPER(TRIM($B37))="AUXILIAR DE COCINA",17,11),1,0))), 1 )) -> 45992 | M36: =IF($K36="","",IF(OR($D36="",$D36<$F36),"PENDIENTE",IF($D36<=$K36,"A TIEMPO","FUERA DE TIEMPO"))) -> A TIEMPO
A37: LILIAM YISET ROMERO BARBOZA | B37: AUXILIAR DE COCINA | C37: CONTRATADO | D37: 46031 | E37: ANGIE | F37: 46003 | H37: YENIFER PAOLA MORENO PEREZ | K37: {=IF(OR($B37="",$F37=""),"",WORKDAY.INTL(IF(ISNUMBER($F37),$F37,FECHA.VALOR($F37)),IF(UPPER(TRIM($B37))="AUXILIAR DE COCINA",10,15),1,FESTIVOS!$A$3:$A$1000))} -> 46020 | L37: =IF($F38="","",DATE( YEAR(EDATE($F38,IF(DAY($F38)>=IF(UPPER(TRIM($B38))="AUXILIAR DE COCINA",17,11),1,0))), MONTH(EDATE($F38,IF(DAY($F38)>=IF(UPPER(TRIM($B38))="AUXILIAR DE COCINA",17,11),1,0))), 1 )) -> 45992 | M37: =IF($K37="","",IF(OR($D37="",$D37<$F37),"PENDIENTE",IF($D37<=$K37,"A TIEMPO","FUERA DE TIEMPO"))) -> FUERA DE TIEMPO
A38: YUDY NATALIA FLOREZ MANCO | B38: AUXILIAR DE COCINA | C38: CONTRATADO | D38: 46029 | E38: ANGIE | F38: 46003 | H38: JESUS ALBERTO SEPULVEDA BELTRAN | K38: {=IF(OR($B38="",$F38=""),"",WORKDAY.INTL(IF(ISNUMBER($F38),$F38,FECHA.VALOR($F38)),IF(UPPER(TRIM($B38))="AUXILIAR DE COCINA",10,15),1,FESTIVOS!$A$3:$A$1000))} -> 46020 | L38: =IF($F39="","",DATE( YEAR(EDATE($F39,IF(DAY($F39)>=IF(UPPER(TRIM($B39))="AUXILIAR DE COCINA",17,11),1,0))), MONTH(EDATE($F39,IF(DAY($F39)>=IF(UPPER(TRIM($B39))="AUXILIAR DE COCINA",17,11),1,0))), 1 )) -> 45992 | M38: =IF($K38="","",IF(OR($D38="",$D38<$F38),"PENDIENTE",IF($D38<=$K38,"A TIEMPO","FUERA DE TIEMPO"))) -> FUERA DE TIEMPO
A39: SUSANA RIOS MEJIA | B39: AUXILIAR DE COCINA | C39: CONTRATADO | D39: 46031 | E39: ANGIE | F39: 46003 | H39: LEIDIS TATIANA MONTERROZA GIL | K39: {=IF(OR($B39="",$F39=""),"",WORKDAY.INTL(IF(ISNUMBER($F39),$F39,FECHA.VALOR($F39)),IF(UPPER(TRIM($B39))="AUXILIAR DE COCINA",10,15),1,FESTIVOS!$A$3:$A$1000))} -> 46020 | L39: =IF($F40="","",DATE( YEAR(EDATE($F40,IF(DAY($F40)>=IF(UPPER(TRIM($B40))="AUXILIAR DE COCINA",17,11),1,0))), MONTH(EDATE($F40,IF(DAY($F40)>=IF(UPPER(TRIM($B40))="AUXILIAR DE COCINA",17,11),1,0))), 1 )) -> 45992 | M39: =IF($K39="","",IF(OR($D39="",$D39<$F39),"PENDIENTE",IF($D39<=$K39,"A TIEMPO","FUERA DE TIEMPO"))) -> FUERA DE TIEMPO
A40: YORLEIDYS PEÑATA HERRERA | B40: AUXILIAR DE COCINA | C40: CONTRATADO | D40: 46031 | E40: ANGIE | F40: 46003 | H40: LEIDY DIANA MONTERROSA GIL | K40: {=IF(OR($B40="",$F40=""),"",WORKDAY.INTL(IF(ISNUMBER($F40),$F40,FECHA.VALOR($F40)),IF(UPPER(TRIM($B40))="AUXILIAR DE COCINA",10,15),1,FESTIVOS!$A$3:$A$1000))} -> 46020 | L40: =IF(#REF!="","",DATE( YEAR(EDATE(#REF!,IF(DAY(#REF!)>=IF(UPPER(TRIM(#REF!))="AUXILIAR DE COCINA",17,11),1,0))), MONTH(EDATE(#REF!,IF(DAY(#REF!)>=IF(UPPER(TRIM(#REF!))="AUXILIAR DE COCINA",17,11),1,0))), 1 )) -> #REF! | M40: =IF($K40="","",IF(OR($D40="",$D40<$F40),"PENDIENTE",IF($D40<=$K40,"A TIEMPO","FUERA DE TIEMPO"))) -> FUERA DE TIEMPO
...

Sheet RIONEGRO
A1: NOMBRE NUEVO INGRESO | B1: CARGO | C1: ESTADO | D1: FECHA DE INGRESO | E1: SOLICITA | F1: FECHA DE SOLICITUD | G1: PUNTO | H1: PERSONA A QUIEN REEMPLAZARA | I1: POSICION CLAVES | J1: MOTIVO | K1: FECHA MAXIMA | L1: MES_INDICADOR_K | M1: ESTADO DEL INGRESO
A2: YULIANA MOSQIERA MOSQUERA | B2: AUXILIAR DE COCINA | C2: CONTRATADO | D2: 46031 | E2: ANGIE | F2: 46003 | G2: SAN NICOLAS | H2: ROSELYN VALERO DE LOPEZ | K2: {=IF(OR($B2="",$F2=""),"",WORKDAY.INTL(IF(ISNUMBER($F2),$F2,FECHA.VALOR($F2)),IF(UPPER(TRIM($B2))="AUXILIAR DE COCINA",10,15),1,FESTIVOS!$A$3:$A$1000))} -> 46020 | L2: =IF($F3="","",DATE( YEAR(EDATE($F3,IF(DAY($F3)>=IF(UPPER(TRIM($B3))="AUXILIAR DE COCINA",17,11),1,0))), MONTH(EDATE($F3,IF(DAY($F3)>=IF(UPPER(TRIM($B3))="AUXILIAR DE COCINA",17,11),1,0))), 1 )) -> 46023 | M2: =IF($K2="","",IF(OR($D2="",$D2<$F2),"PENDIENTE",IF($D2<=$K2,"A TIEMPO","FUERA DE TIEMPO"))) -> FUERA DE TIEMPO
A3: ANDRES FELIPE RODRIGUEZ | B3: AUXILIAR DE COCINA | C3: CONTRATADO | D3: 46031 | E3: ANGIE | F3: 46013 | G3: SAN NICOLAS | H3: BASTIDAS KLEVER YUSMELIS DEL CARMEN | K3: {=IF(OR($B3="",$F3=""),"",WORKDAY.INTL(IF(ISNUMBER($F3),$F3,FECHA.VALOR($F3)),IF(UPPER(TRIM($B3))="AUXILIAR DE COCINA",10,15),1,FESTIVOS!$A$3:$A$1000))} -> 46029 | L3: =IF($F4="","",DATE( YEAR(EDATE($F4,IF(DAY($F4)>=IF(UPPER(TRIM($B4))="AUXILIAR DE COCINA",17,11),1,0))), MONTH(EDATE($F4,IF(DAY($F4)>=IF(UPPER(TRIM($B4))="AUXILIAR DE COCINA",17,11),1,0))), 1 )) -> 46023 | M3: =IF($K3="","",IF(OR($D3="",$D3<$F3),"PENDIENTE",IF($D3<=$K3,"A TIEMPO","FUERA DE TIEMPO"))) -> FUERA DE TIEMPO
A4: LILIANA GUILLEN FUENTES | B4: AUXILIAR DE COCINA | C4: CONTRATADO | D4: 46038 | E4: ANGIE | F4: 46029 | G4: SAN NICOLAS | H4: BASTIDAS KLEVER YUSMELIS DEL CARMEN | I4: AUXILIAR | J4: RENUNCIA | K4: {=IF(OR($B4="",$F4=""),"",WORKDAY.INTL(IF(ISNUMBER($F4),$F4,FECHA.VALOR($F4)),IF(UPPER(TRIM($B4))="AUXILIAR DE COCINA",10,15),1,FESTIVOS!$A$3:$A$1000))} -> 46044 | L4: =IF($F5="","",DATE( YEAR(EDATE($F5,IF(DAY($F5)>=IF(UPPER(TRIM($B5))="AUXILIAR DE COCINA",17,11),1,0))), MONTH(EDATE($F5,IF(DAY($F5)>=IF(UPPER(TRIM($B5))="AUXILIAR DE COCINA",17,11),1,0))), 1 )) -> 46023 | M4: =IF($K4="","",IF(OR($D4="",$D4<$F4),"PENDIENTE",IF($D4<=$K4,"A TIEMPO","FUERA DE TIEMPO"))) -> A TIEMPO
A5: EDINSON JAVIER VILORIA | B5: AUXILIAR DE COCINA | C5: CONTRATADO | D5: 46038 | E5: ANGIE | F5: 46029 | G5: SAN NICOLAS | H5: ROSELYN VALERO DE LOPEZ | I5: AUXILIAR | J5: RENUNCIA | K5: {=IF(OR($B5="",$F5=""),"",WORKDAY.INTL(IF(ISNUMBER($F5),$F5,FECHA.VALOR($F5)),IF(UPPER(TRIM($B5))="AUXILIAR DE COCINA",10,15),1,FESTIVOS!$A$3:$A$1000))} -> 46044 | L5: =IF($F6="","",DATE( YEAR(EDATE($F6,IF(DAY($F6)>=IF(UPPER(TRIM($B6))="AUXILIAR DE COCINA",17,11),1,0))), MONTH(EDATE($F6,IF(DAY($F6)>=IF(UPPER(TRIM($B6))="AUXILIAR DE COCINA",17,11),1,0))), 1 )) -> 46054 | M5: =IF($K5="","",IF(OR($D5="",$D5<$F5),"PENDIENTE",IF($D5<=$K5,"A TIEMPO","FUERA DE TIEMPO"))) -> A TIEMPO
A6: Rafael Humberto Echeverri Cerón | B6: AUXILIAR DE COCINA | C6: CONTRATADO | D6: 46044 | E6: ANGIE | F6: 46041 | G6: SAN NICOLAS | H6: JUAN CARLOS ZAPATA MARIN | I6: AUXILIAR | J6: RENUNCIA | K6: {=IF(OR($B6="",$F6=""),"",WORKDAY.INTL(IF(ISNUMBER($F6),$F6,FECHA.VALOR($F6)),IF(UPPER(TRIM($B6))="AUXILIAR DE COCINA",10,15),1,FESTIVOS!$A$3:$A$1000))} -> 46055 | L6: =IF($F7="","",DATE( YEAR(EDATE($F7,IF(DAY($F7)>=IF(UPPER(TRIM($B7))="AUXILIAR DE COCINA",17,11),1,0))), MONTH(EDATE($F7,IF(DAY($F7)>=IF(UPPER(TRIM($B7))="AUXILIAR DE COCINA",17,11),1,0))), 1 )) -> 46054 | M6: =IF($K6="","",IF(OR($D6="",$D6<$F6),"PENDIENTE",IF($D6<=$K6,"A TIEMPO","FUERA DE TIEMPO"))) -> A TIEMPO
A7: Isabela Negrete Sanchez | B7: AUXILIAR DE COCINA | C7: CONTRATADO | D7: 46042 | E7: ANGIE | F7: 46041 | G7: SAN NICOLAS | H7: VERA ATENCIA ANAHYS PAOLA | I7: AUXILIAR | J7: RENUNCIA | K7: {=IF(OR($B7="",$F7=""),"",WORKDAY.INTL(IF(ISNUMBER($F7),$F7,FECHA.VALOR($F7)),IF(UPPER(TRIM($B7))="AUXILIAR DE COCINA",10,15),1,FESTIVOS!$A$3:$A$1000))} -> 46055 | L7: =IF($F8="","",DATE( YEAR(EDATE($F8,IF(DAY($F8)>=IF(UPPER(TRIM($B8))="AUXILIAR DE COCINA",17,11),1,0))), MONTH(EDATE($F8,IF(DAY($F8)>=IF(UPPER(TRIM($B8))="AUXILIAR DE COCINA",17,11),1,0))), 1 )) -> 46054 | M7: =IF($K7="","",IF(OR($D7="",$D7<$F7),"PENDIENTE",IF($D7<=$K7,"A TIEMPO","FUERA DE TIEMPO"))) -> A TIEMPO
A8: GENESIS GOMEZ | B8: AUXILIAR DE SERVICIO | C8: CONTRATADO | D8: 46042 | E8: ANGIE | F8: 46041 | G8: SAN NICOLAS | H8: ? | K8: {=IF(OR($B8="",$F8=""),"",WORKDAY.INTL(IF(ISNUMBER($F8),$F8,FECHA.VALOR($F8)),IF(UPPER(TRIM($B8))="AUXILIAR DE COCINA",10,15),1,FESTIVOS!$A$3:$A$1000))} -> 46062 | L8: =IF(#REF!="","",DATE( YEAR(EDATE(#REF!,IF(DAY(#REF!)>=IF(UPPER(TRIM(#REF!))="AUXILIAR DE COCINA",17,11),1,0))), MONTH(EDATE(#REF!,IF(DAY(#REF!)>=IF(UPPER(TRIM(#REF!))="AUXILIAR DE COCINA",17,11),1,0))), 1 )) -> #REF! | M8: =IF($K8="","",IF(OR($D8="",$D8<$F8),"PENDIENTE",IF($D8<=$K8,"A TIEMPO","FUERA DE TIEMPO"))) -> A TIEMPO
A9: ALEXANDRA PINT | B9: AUXILIAR DE COCINA | C9: CONTRATADO | D9: 46083 | E9: ANGIE | F9: 46071 | G9: SAN NICOLAS | H9: JEISON JAVIER VILORA | I9: AUXILIAR | J9: RENUNCIA | K9: {=IF(OR($B9="",$F9=""),"",WORKDAY.INTL(IF(ISNUMBER($F9),$F9,FECHA.VALOR($F9)),IF(UPPER(TRIM($B9))="AUXILIAR DE COCINA",10,15),1,FESTIVOS!$A$3:$A$1000))} -> 46085 | L9: =IF($F10="","",DATE( YEAR(EDATE($F10,IF(DAY($F10)>=IF(UPPER(TRIM($B10))="AUXILIAR DE COCINA",17,11),1,0))), MONTH(EDATE($F10,IF(DAY($F10)>=IF(UPPER(TRIM($B10))="AUXILIAR DE COCINA",17,11),1,0))), 1 )) -> 46082 | M9: =IF($K9="","",IF(OR($D9="",$D9<$F9),"PENDIENTE",IF($D9<=$K9,"A TIEMPO","FUERA DE TIEMPO"))) -> A TIEMPO
A10: MATEO PINEDA | B10: AUXILIAR DE COCINA | C10: CONTRATADO | D10: 46090 | E10: ANGIE | F10: 46076 | G10: SAN NICOLAS | H10: MARIA ISABEL GUARIN | I10: AUXILIAR | J10: TERMINACION DE CT | K10: {=IF(OR($B10="",$F10=""),"",WORKDAY.INTL(IF(ISNUMBER($F10),$F10,FECHA.VALOR($F10)),IF(UPPER(TRIM($B10))="AUXILIAR DE COCINA",10,15),1,FESTIVOS!$A$3:$A$1000))} -> 46090 | L10: =IF($F11="","",DATE( YEAR(EDATE($F11,IF(DAY($F11)>=IF(UPPER(TRIM($B11))="AUXILIAR DE COCINA",17,11),1,0))), MONTH(EDATE($F11,IF(DAY($F11)>=IF(UPPER(TRIM($B11))="AUXILIAR DE COCINA",17,11),1,0))), 1 )) -> 46082 | M10: =IF($K10="","",IF(OR($D10="",$D10<$F10),"PENDIENTE",IF($D10<=$K10,"A TIEMPO","FUERA DE TIEMPO"))) -> A TIEMPO
A11: NEYELI ANDREA PITALUA CARO | B11: CAJERO | C11: CONTRATADO | D11: 46120 | E11: ANGIE | F11: 46088 | G11: SAN NICOLAS | H11: RODRIGUEZ TALERO EDITH YOHANNA | I11: AUXILIAR | J11: TERMINACION DE CT | K11: {=IF(OR($B11="",$F11=""),"",WORKDAY.INTL(IF(ISNUMBER($F11),$F11,FECHA.VALOR($F11)),IF(UPPER(TRIM($B11))="AUXILIAR DE COCINA",10,15),1,FESTIVOS!$A$3:$A$1000))} -> 46111 | L11: =IF($F12="","",DATE( YEAR(EDATE($F12,IF(DAY($F12)>=IF(UPPER(TRIM($B12))="AUXILIAR DE COCINA",17,11),1,0))), MONTH(EDATE($F12,IF(DAY($F12)>=IF(UPPER(TRIM($B12))="AUXILIAR DE COCINA",17,11),1,0))), 1 )) | M11: =IF($K11="","",IF(OR($D11="",$D11<$F11),"PENDIENTE",IF($D11<=$K11,"A TIEMPO","FUERA DE TIEMPO"))) -> FUERA DE TIEMPO
B12: AUXILIAR DE COCINA-TIEMPOS | E12: ANGIE | G12: SAN NICOLAS | H12: RAFAEL HUMBERTO TALERO | I12: AUXILIAR | J12: TERMINACION DE CT
A13: GEIDYS KARINA GARRIDO CARO | B13: AUXILIAR DE COCINA | C13: CONTRATADO | D13: 46118 | E13: ANGIE | F13: 46099 | G13: SAN NICOLAS | H13: MATEO PINEDA | I13: AUXILIAR | J13: RENUNCIA | K13: {=IF(OR($B13="",$F13=""),"",WORKDAY.INTL(IF(ISNUMBER($F13),$F13,FECHA.VALOR($F13)),IF(UPPER(TRIM($B13))="AUXILIAR DE COCINA",10,15),1,FESTIVOS!$A$3:$A$1000))} -> 46118 | L13: =IF($F14="","",DATE( YEAR(EDATE($F14,IF(DAY($F14)>=IF(UPPER(TRIM($B14))="AUXILIAR DE COCINA",17,11),1,0))), MONTH(EDATE($F14,IF(DAY($F14)>=IF(UPPER(TRIM($B14))="AUXILIAR DE COCINA",17,11),1,0))), 1 )) -> 46113 | M13: =IF($K13="","",IF(OR($D13="",$D13<$F13),"PENDIENTE",IF($D13<=$K13,"A TIEMPO","FUERA DE TIEMPO"))) -> A TIEMPO
A14: TATIANA SALCEDO BRICEÑO | B14: AUXILIAR DE SERVICIO | C14: CONTRATADO | D14: 46182 | E14: ANGIE | F14: 46106 | G14: SAN NICOLAS | H14: ISABELA NEGRETE | I14: AUXILIAR | J14: RENUNCIA | K14: {=IF(OR($B14="",$F14=""),"",WORKDAY.INTL(IF(ISNUMBER($F14),$F14,FECHA.VALOR($F14)),IF(UPPER(TRIM($B14))="AUXILIAR DE COCINA",10,15),1,FESTIVOS!$A$3:$A$1000))} -> 46129 | L14: =IF($F15="","",DATE( YEAR(EDATE($F15,IF(DAY($F15)>=IF(UPPER(TRIM($B15))="AUXILIAR DE COCINA",17,11),1,0))), MONTH(EDATE($F15,IF(DAY($F15)>=IF(UPPER(TRIM($B15))="AUXILIAR DE COCINA",17,11),1,0))), 1 )) -> 46113 | M14: =IF($K14="","",IF(OR($D14="",$D14<$F14),"PENDIENTE",IF($D14<=$K14,"A TIEMPO","FUERA DE TIEMPO"))) -> FUERA DE TIEMPO
A15: Dario cobaleda rodriguez | B15: AUXILIAR DE COCINA | C15: CONTRATADO | D15: 46141 | E15: ANGIE | F15: 46115 | G15: SAN NICOLAS | H15: LILIANA GUILLEN | I15: AUXILIAR | J15: RENUNCIA | K15: {=IF(OR($B15="",$F15=""),"",WORKDAY.INTL(IF(ISNUMBER($F15),$F15,FECHA.VALOR($F15)),IF(UPPER(TRIM($B15))="AUXILIAR DE COCINA",10,15),1,FESTIVOS!$A$3:$A$1000))} -> 46129 | L15: =IF($F16="","",DATE( YEAR(EDATE($F16,IF(DAY($F16)>=IF(UPPER(TRIM($B16))="AUXILIAR DE COCINA",17,11),1,0))), MONTH(EDATE($F16,IF(DAY($F16)>=IF(UPPER(TRIM($B16))="AUXILIAR DE COCINA",17,11),1,0))), 1 )) | M15: =IF($K15="","",IF(OR($D15="",$D15<$F15),"PENDIENTE",IF($D15<=$K15,"A TIEMPO","FUERA DE TIEMPO"))) -> FUERA DE TIEMPO
A16: APARTIR DEL 12-05-2026
A17: Jose David Chacón Marín | B17: SUPERNUMERARIO DE SERVICIO | C17: CONTRATADO | D17: 46171 | E17: ANGIE | F17: 46154 | G17: SAN NICOLAS | H17: DENIS BLANCO | I17: AUXILIAR
A18: Nicolás Esteban Arteaga Madrid | B18: AUXILIAR DE COCINA | C18: CONTRATADO | D18: 46175 | E18: ANGIE | F18: 46168 | G18: SAN NICOLAS | H18: RENUNCIA | I18: AUXILIAR
A19: MAYRIN RUIZ | B19: CAJERO | C19: CONTRATADO | D19: 46197 | E19: ANGIE | F19: 46191 | G19: SAN NICOLAS | H19: NO PRROGA DE CAJERA | I19: AUXILIAR
A20: Cruz Maria Fernandez Hernandez | B20: SUPERNUMERARIO DE SERVICIO | C20: CONTRATADO | D20: 46230 | E20: ANGIE | F20: 46217 | G20: SAN NICOLAS | H20: ALEZANDRA PINTO FLOREZ | I20: AUXILIAR
B21: AUXILIAR DE COCINA | E21: ANGIE | F21: 46219 | G21: SAN NICOLAS | H21: JUAN DIEGO GABALO | I21: PERFIL
A22: ELIZABETH VALENTINA BERRIO BEDOYA | B22: AUXILIAR DE SERVICIO | C22: CONTRATADO | D22: 46230 | E22: ANGIE | F22: 46232 | G22: SAN NICOLAS | H22: JOSE DAVID CHACON | I22: AUXILIAR
B23: LIDER DE COCINA | E23: ANGIE | F23: 46231 | G23: SAN NICOLAS | H23: YEISON LUIS | I23: LIDER
B24: AUXILIAR DE COCINA | E24: ANGIE | G24: SAN NICOLAS | H24: PERSONA APROBADA POR JUAN | I24: AUXILIAR

Sheet BOGOTA
A1: NOMBRE NUEVO INGRESO | B1: CARGO | C1: ESTADO | D1: FECHA DE INGRESO | E1: SOLICITA | F1: FECHA DE SOLICITUD | G1: PUNTO | H1: PERSONA A QUIEN REEMPLAZARA | I1: POSICION CLAVES | J1: MOTIVO | K1: FECHA MAXIMA | L1: MES_INDICADOR_K | M1: ESTADO DEL INGRESO | N1: OBSERVACION
A2: PEÑA LOPEZ SERGIO NICOLAS | B2: AUXILIAR DE COCINA | C2: CONTRATADO | D2: 45995 | E2: SEBASTIAN | F2: 45992 | G2: SUPERNUMERARIO | H2: HORTAS VANEGAS VALENTINA | K2: {=IF(OR($B2="",$F2=""),"",WORKDAY.INTL(IF(ISNUMBER($F2),$F2,FECHA.VALOR($F2)),IF(UPPER(TRIM($B2))="AUXILIAR DE COCINA",7,10),1,FESTIVOS!$D$3:$D$996))} -> 46002 | L2: =IF($F2="","",DATE(YEAR(EDATE($F2,IF(DAY($F2)>=17,1,0))),MONTH(EDATE($F2,IF(DAY($F2)>=17,1,0))),1)) -> 45992 | M2: =IF($K2="","",IF(OR($D2="",$D2<$F2),"PENDIENTE",IF($D2<=$K2,"A TIEMPO","FUERA DE TIEMPO"))) -> A TIEMPO | O2: Cuenta de FECHA MAXIMA | P2: ESTADO DEL INGRESO
A3: ROJAS ORTIZ LINDA STEFANY | B3: AUXILIAR DE COCINA | C3: CONTRATADO | D3: 45995 | E3: JESUS | F3: 45992 | G3: SUPERNUMERARIO | H3: LOZANO GAITAN JULIAN ESTID | K3: {=IF(OR($B3="",$F3=""),"",WORKDAY.INTL(IF(ISNUMBER($F3),$F3,FECHA.VALOR($F3)),IF(UPPER(TRIM($B3))="AUXILIAR DE COCINA",7,10),1,FESTIVOS!$D$3:$D$996))} -> 46002 | L3: =IF($F3="","",DATE(YEAR(EDATE($F3,IF(DAY($F3)>=17,1,0))),MONTH(EDATE($F3,IF(DAY($F3)>=17,1,0))),1)) -> 45992 | M3: =IF($K3="","",IF(OR($D3="",$D3<$F3),"PENDIENTE",IF($D3<=$K3,"A TIEMPO","FUERA DE TIEMPO"))) -> A TIEMPO | O3: MES_INDICADOR_K | P3: A TIEMPO | Q3: PENDIENTE | R3: Total general
A4: RODRIGUEZ MENDIVELSO ALAN | B4: AUXILIAR DE COCINA | C4: CONTRATADO | D4: 46002 | E4: SEBASTIAN | F4: 45996 | G4: TITAN | H4: USTARIZ SAURITH YESITH PAOLA | K4: {=IF(OR($B4="",$F4=""),"",WORKDAY.INTL(IF(ISNUMBER($F4),$F4,FECHA.VALOR($F4)),IF(UPPER(TRIM($B4))="AUXILIAR DE COCINA",7,10),1,FESTIVOS!$D$3:$D$996))} -> 46008 | L4: =IF($F4="","",DATE(YEAR(EDATE($F4,IF(DAY($F4)>=17,1,0))),MONTH(EDATE($F4,IF(DAY($F4)>=17,1,0))),1)) -> 45992 | M4: =IF($K4="","",IF(OR($D4="",$D4<$F4),"PENDIENTE",IF($D4<=$K4,"A TIEMPO","FUERA DE TIEMPO"))) -> A TIEMPO | O4: 45992 | P4: 9 | R4: 9
A5: MONTALVO ZAMBRANO CARLOS ANTONIO | B5: AUXILIAR DE COCINA | C5: CONTRATADO | D5: 46002 | E5: SEBASTIAN | F5: 46001 | G5: SUPERNUMERARIO | H5: GAITAN SEDANO BRAYAN EDILSON | K5: {=IF(OR($B5="",$F5=""),"",WORKDAY.INTL(IF(ISNUMBER($F5),$F5,FECHA.VALOR($F5)),IF(UPPER(TRIM($B5))="AUXILIAR DE COCINA",7,10),1,FESTIVOS!$D$3:$D$996))} -> 46010 | L5: =IF($F5="","",DATE(YEAR(EDATE($F5,IF(DAY($F5)>=17,1,0))),MONTH(EDATE($F5,IF(DAY($F5)>=17,1,0))),1)) -> 45992 | M5: =IF($K5="","",IF(OR($D5="",$D5<$F5),"PENDIENTE",IF($D5<=$K5,"A TIEMPO","FUERA DE TIEMPO"))) -> A TIEMPO | O5: 46023 | P5: 3 | Q5: 5 | R5: 8
A6: SEVERICHE CHICA JAIRIS | B6: AUXILIAR DE SERVICIO | C6: CONTRATADO | D6: 46002 | E6: JESUS | F6: 46001 | G6: SUPERNUMERARIO | H6: SORIANO CADENA ALEJANDRO | K6: {=IF(OR($B6="",$F6=""),"",WORKDAY.INTL(IF(ISNUMBER($F6),$F6,FECHA.VALOR($F6)),IF(UPPER(TRIM($B6))="AUXILIAR DE COCINA",7,10),1,FESTIVOS!$D$3:$D$996))} -> 46015 | L6: =IF($F6="","",DATE(YEAR(EDATE($F6,IF(DAY($F6)>=17,1,0))),MONTH(EDATE($F6,IF(DAY($F6)>=17,1,0))),1)) -> 45992 | M6: =IF($K6="","",IF(OR($D6="",$D6<$F6),"PENDIENTE",IF($D6<=$K6,"A TIEMPO","FUERA DE TIEMPO"))) -> A TIEMPO | O6: Total general | P6: 12 | Q6: 5 | R6: 17
A7: HORTA CARRILLO SAMIR ENRIQUE | B7: AUXILIAR DE COCINA | C7: CONTRATADO | D7: 46009 | E7: SEBASTIAN | F7: 46002 | G7: SUPERNUMERARIO | H7: PEÑA LOPEZ SERGIO NICOLAS | K7: {=IF(OR($B7="",$F7=""),"",WORKDAY.INTL(IF(ISNUMBER($F7),$F7,FECHA.VALOR($F7)),IF(UPPER(TRIM($B7))="AUXILIAR DE COCINA",7,10),1,FESTIVOS!$D$3:$D$996))} -> 46013 | L7: =IF($F7="","",DATE(YEAR(EDATE($F7,IF(DAY($F7)>=17,1,0))),MONTH(EDATE($F7,IF(DAY($F7)>=17,1,0))),1)) -> 45992 | M7: =IF($K7="","",IF(OR($D7="",$D7<$F7),"PENDIENTE",IF($D7<=$K7,"A TIEMPO","FUERA DE TIEMPO"))) -> A TIEMPO
A8: ROSAS JUAN ESTEBAN | B8: AUXILIAR DE COCINA | C8: CONTRATADO | D8: 46009 | E8: SEBASTIAN | F8: 46003 | G8: SUPERNUMERARIO | H8: TRES PALACIOS JUAN CAMILO | K8: {=IF(OR($B8="",$F8=""),"",WORKDAY.INTL(IF(ISNUMBER($F8),$F8,FECHA.VALOR($F8)),IF(UPPER(TRIM($B8))="AUXILIAR DE COCINA",7,10),1,FESTIVOS!$D$3:$D$996))} -> 46014 | L8: =IF($F8="","",DATE(YEAR(EDATE($F8,IF(DAY($F8)>=17,1,0))),MONTH(EDATE($F8,IF(DAY($F8)>=17,1,0))),1)) -> 45992 | M8: =IF($K8="","",IF(OR($D8="",$D8<$F8),"PENDIENTE",IF($D8<=$K8,"A TIEMPO","FUERA DE TIEMPO"))) -> A TIEMPO
A9: CORTES RIVERA YEYNNE JOHANNA | B9: AUXILIAR DE COCINA | C9: CONTRATADO | D9: 46009 | E9: SEBASTIAN | F9: 46003 | G9: SUPERNUMERARIO | H9: VIRGUEZ SUAREZ YEISON ALEXANDER | K9: {=IF(OR($B9="",$F9=""),"",WORKDAY.INTL(IF(ISNUMBER($F9),$F9,FECHA.VALOR($F9)),IF(UPPER(TRIM($B9))="AUXILIAR DE COCINA",7,10),1,FESTIVOS!$D$3:$D$996))} -> 46014 | L9: =IF($F9="","",DATE(YEAR(EDATE($F9,IF(DAY($F9)>=17,1,0))),MONTH(EDATE($F9,IF(DAY($F9)>=17,1,0))),1)) -> 45992 | M9: =IF($K9="","",IF(OR($D9="",$D9<$F9),"PENDIENTE",IF($D9<=$K9,"A TIEMPO","FUERA DE TIEMPO"))) -> A TIEMPO
A10: MEJIA BURGOS ENIRLEYDIS | B10: AUXILIAR DE SERVICIO | C10: CONTRATADO | D10: 46009 | E10: SEBASTIAN | F10: 46007 | G10: TITAN | H10: SANTA AGUDELO CARLOS ALBERTO | K10: {=IF(OR($B10="",$F10=""),"",WORKDAY.INTL(IF(ISNUMBER($F10),$F10,FECHA.VALOR($F10)),IF(UPPER(TRIM($B10))="AUXILIAR DE COCINA",7,10),1,FESTIVOS!$D$3:$D$996))} -> 46022 | L10: =IF($F10="","",DATE(YEAR(EDATE($F10,IF(DAY($F10)>=17,1,0))),MONTH(EDATE($F10,IF(DAY($F10)>=17,1,0))),1)) -> 45992 | M10: =IF($K10="","",IF(OR($D10="",$D10<$F10),"PENDIENTE",IF($D10<=$K10,"A TIEMPO","FUERA DE TIEMPO"))) -> A TIEMPO
A11: ORTEGA OSORIO LEONARDO JOSE | B11: AUXILIAR DE COCINA | C11: CONTRATADO | D11: 46009 | E11: SEBASTIAN | F11: 46008 | G11: SUPERNUMERARIO | H11: OLIVARES PEREZ LUIS JOSE | K11: {=IF(OR($B11="",$F11=""),"",WORKDAY.INTL(IF(ISNUMBER($F11),$F11,FECHA.VALOR($F11)),IF(UPPER(TRIM($B11))="AUXILIAR DE COCINA",7,10),1,FESTIVOS!$D$3:$D$996))} -> 46020 | L11: =IF($F11="","",DATE(YEAR(EDATE($F11,IF(DAY($F11)>=17,1,0))),MONTH(EDATE($F11,IF(DAY($F11)>=17,1,0))),1)) -> 46023 | M11: =IF($K11="","",IF(OR($D11="",$D11<$F11),"PENDIENTE",IF($D11<=$K11,"A TIEMPO","FUERA DE TIEMPO"))) -> A TIEMPO
A12: CACERES PERDOMO LEIDY CARLINA | B12: AUXILIAR DE SERVICIO | C12: CONTRATADO | D12: 46013 | E12: JESUS | F12: 46009 | G12: SUPERNUMERARIO | H12: SEVERICHE CHICA JAIRIS | K12: {=IF(OR($B12="",$F12=""),"",WORKDAY.INTL(IF(ISNUMBER($F12),$F12,FECHA.VALOR($F12)),IF(UPPER(TRIM($B12))="AUXILIAR DE COCINA",7,10),1,FESTIVOS!$D$3:$D$996))} -> 46027 | L12: =IF($F12="","",DATE(YEAR(EDATE($F12,IF(DAY($F12)>=17,1,0))),MONTH(EDATE($F12,IF(DAY($F12)>=17,1,0))),1)) -> 46023 | M12: =IF($K12="","",IF(OR($D12="",$D12<$F12),"PENDIENTE",IF($D12<=$K12,"A TIEMPO","FUERA DE TIEMPO"))) -> A TIEMPO
A13: ROMERO BERRIO YARELIS BEATRIZ | B13: AUXILIAR DE COCINA | C13: CONTRATADO | D13: 46009 | E13: SEBASTIAN | F13: 46011 | G13: SUPERNUMERARIO | H13: DOMINGUEZ FRIA YIBRAN JOSE | K13: {=IF(OR($B13="",$F13=""),"",WORKDAY.INTL(IF(ISNUMBER($F13),$F13,FECHA.VALOR($F13)),IF(UPPER(TRIM($B13))="AUXILIAR DE COCINA",7,10),1,FESTIVOS!$D$3:$D$996))} -> 46022 | L13: =IF($F13="","",DATE(YEAR(EDATE($F13,IF(DAY($F13)>=17,1,0))),MONTH(EDATE($F13,IF(DAY($F13)>=17,1,0))),1)) -> 46023 | M13: =IF($K13="","",IF(OR($D13="",$D13<$F13),"PENDIENTE",IF($D13<=$K13,"A TIEMPO","FUERA DE TIEMPO"))) -> PENDIENTE
A14: WANDURRUAGA REYES MARIO ALEJANDRO | B14: AUXILIAR DE COCINA | C14: CONTRATADO | D14: 46027 | E14: SEBASTIAN | F14: 46020 | G14: SUPERNUMERARIO | H14: CORTES RIVERA YEYNNE JOHANNA | K14: {=IF(OR($B14="",$F14=""),"",WORKDAY.INTL(IF(ISNUMBER($F14),$F14,FECHA.VALOR($F14)),IF(UPPER(TRIM($B14))="AUXILIAR DE COCINA",7,10),1,FESTIVOS!$D$3:$D$996))} -> 46030 | L14: =IF($F14="","",DATE(YEAR(EDATE($F14,IF(DAY($F14)>=17,1,0))),MONTH(EDATE($F14,IF(DAY($F14)>=17,1,0))),1)) -> 46023 | M14: =IF($K14="","",IF(OR($D14="",$D14<$F14),"PENDIENTE",IF($D14<=$K14,"A TIEMPO","FUERA DE TIEMPO"))) -> A TIEMPO
A15: PEÑA RUIZ MARIA GABRIELA | B15: AUXILIAR DE SERVICIO | C15: CONTRATADO | D15: 46041 | E15: JESUS | F15: 46027 | G15: CENTRO MAYOR | H15: TRESPALACIOS GARCIA JUAN DAVID | K15: {=IF(OR($B15="",$F15=""),"",WORKDAY.INTL(IF(ISNUMBER($F15),$F15,FECHA.VALOR($F15)),IF(UPPER(TRIM($B15))="AUXILIAR DE COCINA",7,10),1,FESTIVOS!$D$3:$D$996))} -> 46042 | L15: =IF($F15="","",DATE(YEAR(EDATE($F15,IF(DAY($F15)>=17,1,0))),MONTH(EDATE($F15,IF(DAY($F15)>=17,1,0))),1)) -> 46023 | M15: =IF($K15="","",IF(OR($D15="",$D15<$F15),"PENDIENTE",IF($D15<=$K15,"A TIEMPO","FUERA DE TIEMPO"))) -> A TIEMPO
A16: NORIEGA ALVAREZ AUREN FELIPE | B16: AUXILIAR DE COCINA | C16: CONTRATADO | D16: 46030 | E16: JESUS | F16: 46027 | G16: CENTRO MAYOR | H16: CAMACHO HERRERA DIEGO MARIO | K16: {=IF(OR($B16="",$F16=""),"",WORKDAY.INTL(IF(ISNUMBER($F16),$F16,FECHA.VALOR($F16)),IF(UPPER(TRIM($B16))="AUXILIAR DE COCINA",7,10),1,FESTIVOS!$D$3:$D$996))} -> 46037 | L16: =IF($F16="","",DATE(YEAR(EDATE($F16,IF(DAY($F16)>=17,1,0))),MONTH(EDATE($F16,IF(DAY($F16)>=17,1,0))),1)) -> 46023 | M16: =IF($K16="","",IF(OR($D16="",$D16<$F16),"PENDIENTE",IF($D16<=$K16,"A TIEMPO","FUERA DE TIEMPO"))) -> A TIEMPO
A17: PICON TORRES HILMER | B17: AUXILIAR DE COCINA | C17: CONTRATADO | D17: 46030 | E17: SEBASTIAN | F17: 46028 | G17: BACKUP | H17: MOLINA PEREZ HAROLD JUNIOR | K17: {=IF(OR($B17="",$F17=""),"",WORKDAY.INTL(IF(ISNUMBER($F17),$F17,FECHA.VALOR($F17)),IF(UPPER(TRIM($B17))="AUXILIAR DE COCINA",7,10),1,FESTIVOS!$D$3:$D$996))} -> 46038 | L17: =IF($F17="","",DATE(YEAR(EDATE($F17,IF(DAY($F17)>=17,1,0))),MONTH(EDATE($F17,IF(DAY($F17)>=17,1,0))),1)) -> 46023 | M17: =IF($K17="","",IF(OR($D17="",$D17<$F17),"PENDIENTE",IF($D17<=$K17,"A TIEMPO","FUERA DE TIEMPO"))) -> A TIEMPO
A18: SOLANO GUERRERO MAYERLYN VIRGINIA | B18: AUXILIAR DE SERVICIO | C18: CONTRATADO | D18: 46030 | E18: JESUS | F18: 46028 | G18: SUPERNUMERARIO | H18: DURAN TOVAR MARIA ANGELICA | K18: {=IF(OR($B18="",$F18=""),"",WORKDAY.INTL(IF(ISNUMBER($F18),$F18,FECHA.VALOR($F18)),IF(UPPER(TRIM($B18))="AUXILIAR DE COCINA",7,10),1,FESTIVOS!$D$3:$D$996))} -> 46043 | L18: =IF($F18="","",DATE(YEAR(EDATE($F18,IF(DAY($F18)>=17,1,0))),MONTH(EDATE($F18,IF(DAY($F18)>=17,1,0))),1)) -> 46023 | M18: =IF($K18="","",IF(OR($D18="",$D18<$F18),"PENDIENTE",IF($D18<=$K18,"A TIEMPO","FUERA DE TIEMPO"))) -> A TIEMPO
... A28: CAMILA ANDREA DEL VALLE POMBO | B28: AUXILIAR DE COCINA | C28: CONTRATADO | D28: 46046 | E28: ANGIE | F28: 46043 | G28: BACKUP | H28: PICON TORRES HILMER | K28: {=IF(OR($B28="",$F28=""),"",WORKDAY.INTL(IF(ISNUMBER($F28),$F28,FECHA.VALOR($F28)),IF(UPPER(TRIM($B28))="AUXILIAR DE COCINA",7,10),1,FESTIVOS!$D$3:$D$996))} -> 46052 | L28: =IF($F28="","",DATE(YEAR(EDATE($F28,IF(DAY($F28)>=17,1,0))),MONTH(EDATE($F28,IF(DAY($F28)>=17,1,0))),1)) -> 46054 | M28: =IF($K28="","",IF(OR($D28="",$D28<$F28),"PENDIENTE",IF($D28<=$K28,"A TIEMPO","FUERA DE TIEMPO"))) -> A TIEMPO
A29: ORTEGA DIAZ YENI PAOLA | B29: AUXILIAR DE SERVICIO | C29: CONTRATADO | D29: 46047 | E29: ANGIE | F29: 46043 | H29: BACKUP APROBADA DE SERVICIO (+) | K29: {=IF(OR($B29="",$F29=""),"",WORKDAY.INTL(IF(ISNUMBER($F29),$F29,FECHA.VALOR($F29)),IF(UPPER(TRIM($B29))="AUXILIAR DE COCINA",7,10),1,FESTIVOS!$D$3:$D$996))} -> 46057 | L29: =IF($F29="","",DATE(YEAR(EDATE($F29,IF(DAY($F29)>=17,1,0))),MONTH(EDATE($F29,IF(DAY($F29)>=17,1,0))),1)) -> 46054 | M29: =IF($K29="","",IF(OR($D29="",$D29<$F29),"PENDIENTE",IF($D29<=$K29,"A TIEMPO","FUERA DE TIEMPO"))) -> A TIEMPO
A30: GAMBINO GUIZA SANTIAGO | B30: AUXILIAR DE COCINA | C30: CONTRATADO | D30: 46048 | E30: ANGIE | F30: 46042 | H30: FONTALVO CAPELA CALEB DAVID | K30: {=IF(OR($B30="",$F30=""),"",WORKDAY.INTL(IF(ISNUMBER($F30),$F30,FECHA.VALOR($F30)),IF(UPPER(TRIM($B30))="AUXILIAR DE COCINA",7,10),1,FESTIVOS!$D$3:$D$996))} -> 46051 | L30: =IF($F30="","",DATE(YEAR(EDATE($F30,IF(DAY($F30)>=17,1,0))),MONTH(EDATE($F30,IF(DAY($F30)>=17,1,0))),1)) -> 46054 | M30: =IF($K30="","",IF(OR($D30="",$D30<$F30),"PENDIENTE",IF($D30<=$K30,"A TIEMPO","FUERA DE TIEMPO"))) -> A TIEMPO
A31: PRADA CHAPARRO BEIDY LORENA | B31: AUXILIAR DE SERVICIO | C31: CONTRATADO | D31: 46049 | E31: JESUS | F31: 46048 | G31: COLINA | H31: GUARIN RAMIREZ LAIDY JOHANA | K31: {=IF(OR($B31="",$F31=""),"",WORKDAY.INTL(IF(ISNUMBER($F31),$F31,FECHA.VALOR($F31)),IF(UPPER(TRIM($B31))="AUXILIAR DE COCINA",7,10),1,FESTIVOS!$D$3:$D$996))} -> 46062 | L31: =IF($F31="","",DATE(YEAR(EDATE($F31,IF(DAY($F31)>=17,1,0))),MONTH(EDATE($F31,IF(DAY($F31)>=17,1,0))),1)) -> 46054 | M31: =IF($K31="","",IF(OR($D31="",$D31<$F31),"PENDIENTE",IF($D31<=$K31,"A TIEMPO","FUERA DE TIEMPO"))) -> A TIEMPO
A32: SALAZAR AGUAS JULISA PAOLA | B32: AUXILIAR DE SERVICIO | C32: CONTRATADO | D32: 46050 | E32: SEBASTIAN | F32: 46052 | G32: SUPERNUMERARIO | H32: RUIZ RAMOS MARINELA (TRASLADO) | K32: {=IF(OR($B32="",$F32=""),"",WORKDAY.INTL(IF(ISNUMBER($F32),$F32,FECHA.VALOR($F32)),IF(UPPER(TRIM($B32))="AUXILIAR DE COCINA",7,10),1,FESTIVOS!$D$3:$D$996))} -> 46066 | L32: =IF($F32="","",DATE(YEAR(EDATE($F32,IF(DAY($F32)>=17,1,0))),MONTH(EDATE($F32,IF(DAY($F32)>=17,1,0))),1)) -> 46054 | M32: =IF($K32="","",IF(OR($D32="",$D32<$F32),"PENDIENTE",IF($D32<=$K32,"A TIEMPO","FUERA DE TIEMPO"))) -> PENDIENTE
A33: MARTINEZ QUINTERO GEIDIS | B33: AUXILIAR DE COCINA | C33: CONTRATADO | D33: 46051 | E33: SEBASTIAN | F33: 46055 | G33: SUPERNUMERARIO | K33: {=IF(OR($B33="",$F33=""),"",WORKDAY.INTL(IF(ISNUMBER($F33),$F33,FECHA.VALOR($F33)),IF(UPPER(TRIM($B33))="AUXILIAR DE COCINA",7,10),1,FESTIVOS!$D$3:$D$996))} -> 46064 | L33: =IF($F33="","",DATE(YEAR(EDATE($F33,IF(DAY($F33)>=17,1,0))),MONTH(EDATE($F33,IF(DAY($F33)>=17,1,0))),1)) -> 46054 | M33: =IF($K33="","",IF(OR($D33="",$D33<$F33),"PENDIENTE",IF($D33<=$K33,"A TIEMPO","FUERA DE TIEMPO"))) -> PENDIENTE
A34: HOYOS HIMITOLA VICTOR DANILO | B34: AUXILIAR DE SERVICIO | C34: CONTRATADO | D34: 46052 | E34: JESUS | F34: 46055 | G34: COLINA | K34: {=IF(OR($B34="",$F34=""),"",WORKDAY.INTL(IF(ISNUMBER($F34),$F34,FECHA.VALOR($F34)),IF(UPPER(TRIM($B34))="AUXILIAR DE COCINA",7,10),1,FESTIVOS!$D$3:$D$996))} -> 46069 | L34: =IF($F34="","",DATE(YEAR(EDATE($F34,IF(DAY($F34)>=17,1,0))),MONTH(EDATE($F34,IF(DAY($F34)>=17,1,0))),1)) -> 46054 | M34: =IF($K34="","",IF(OR($D34="",$D34<$F34),"PENDIENTE",IF($D34<=$K34,"A TIEMPO","FUERA DE TIEMPO"))) -> PENDIENTE
A35: SUAREZ VELASQUEZ RAUL ANDRES | B35: AUXILIAR DE COCINA | C35: CONTRATADO | D35: 46053 | E35: SEBASTIAN | F35: 46057 | G35: SUPERNUMERARIO | K35: {=IF(OR($B35="",$F35=""),"",WORKDAY.INTL(IF(ISNUMBER($F35),$F35,FECHA.VALOR($F35)),IF(UPPER(TRIM($B35))="AUXILIAR DE COCINA",7,10),1,FESTIVOS!$D$3:$D$996))} -> 46066 | L35: =IF($F35="","",DATE(YEAR(EDATE($F35,IF(DAY($F35)>=17,1,0))),MONTH(EDATE($F35,IF(DAY($F35)>=17,1,0))),1)) -> 46054 | M35: =IF($K35="","",IF(OR($D35="",$D35<$F35),"PENDIENTE",IF($D35<=$K35,"A TIEMPO","FUERA DE TIEMPO"))) -> PENDIENTE
A36: QUIROZ BOLIVAR JOSE MIGUEL | B36: AUXILIAR DE COCINA | C36: CONTRATADO | D36: 46054 | E36: SEBASTIAN | F36: 46062 | G36: SUPERNUMERARIO | K36: {=IF(OR($B36="",$F36=""),"",WORKDAY.INTL(IF(ISNUMBER($F36),$F36,FECHA.VALOR($F36)),IF(UPPER(TRIM($B36))="AUXILIAR DE COCINA",7,10),1,FESTIVOS!$D$3:$D$996))} -> 46071 | L36: =IF($F36="","",DATE(YEAR(EDATE($F36,IF(DAY($F36)>=17,1,0))),MONTH(EDATE($F36,IF(DAY($F36)>=17,1,0))),1)) -> 46054 | M36: =IF($K36="","",IF(OR($D36="",$D36<$F36),"PENDIENTE",IF($D36<=$K36,"A TIEMPO","FUERA DE TIEMPO"))) -> PENDIENTE
A37: MAULETH CRUZ YINETH PAOLA | B37: AUXILIAR DE COCINA | C37: CONTRATADO | D37: 46055 | E37: SEBASTIAN | F37: 46062 | G37: SUPERNUMERARIO | K37: {=IF(OR($B37="",$F37=""),"",WORKDAY.INTL(IF(ISNUMBER($F37),$F37,FECHA.VALOR($F37)),IF(UPPER(TRIM($B37))="AUXILIAR DE COCINA",7,10),1,FESTIVOS!$D$3:$D$996))} -> 46071 | L37: =IF($F37="","",DATE(YEAR(EDATE($F37,IF(DAY($F37)>=17,1,0))),MONTH(EDATE($F37,IF(DAY($F37)>=17,1,0))),1)) -> 46054 | M37: =IF($K37="","",IF(OR($D37="",$D37<$F37),"PENDIENTE",IF($D37<=$K37,"A TIEMPO","FUERA DE TIEMPO"))) -> PENDIENTE
A38: PRADA CHAPARRO BEIDY LORENA | B38: AUXILIAR DE SERVICIO | C38: CONTRATADO | D38: 46058 | E38: JESUS | F38: 46055 | G38: COLINA | H38: VALENCIA GONZALEZ TATIANA | K38: {=IF(OR($B38="",$F38=""),"",WORKDAY.INTL(IF(ISNUMBER($F38),$F38,FECHA.VALOR($F38)),IF(UPPER(TRIM($B38))="AUXILIAR DE COCINA",7,10),1,FESTIVOS!$D$3:$D$996))} -> 46069 | L38: =IF($F38="","",DATE(YEAR(EDATE($F38,IF(DAY($F38)>=17,1,0))),MONTH(EDATE($F38,IF(DAY($F38)>=17,1,0))),1)) -> 46054 | M38: =IF($K38="","",IF(OR($D38="",$D38<$F38),"PENDIENTE",IF($D38<=$K38,"A TIEMPO","FUERA DE TIEMPO"))) -> A TIEMPO
A39: SALAZAR AGUAS JULISA PAOLA | B39: AUXILIAR DE SERVICIO | C39: CONTRATADO | D39: 46058 | E39: SEBASTIAN | F39: 46055 | G39: SUPERNUMERARIO | H39: PEREZ BLANCO ARIEL JOSE | K39: {=IF(OR($B39="",$F39=""),"",WORKDAY.INTL(IF(ISNUMBER($F39),$F39,FECHA.VALOR($F39)),IF(UPPER(TRIM($B39))="AUXILIAR DE COCINA",7,10),1,FESTIVOS!$D$3:$D$996))} -> 46069 | L39: =IF($F39="","",DATE(YEAR(EDATE($F39,IF(DAY($F39)>=17,1,0))),MONTH(EDATE($F39,IF(DAY($F39)>=17,1,0))),1)) -> 46054 | M39: =IF($K39="","",IF(OR($D39="",$D39<$F39),"PENDIENTE",IF($D39<=$K39,"A TIEMPO","FUERA DE TIEMPO"))) -> A TIEMPO
A40: MARTINEZ QUINTERO GEIDIS | B40: AUXILIAR DE COCINA | C40: CONTRATADO | D40: 46058 | E40: SEBASTIAN | F40: 46057 | G40: SUPERNUMERARIO | H40: VIVAS SANEZ JUAN SEBASTIAN | K40: {=IF(OR($B40="",$F40=""),"",WORKDAY.INTL(IF(ISNUMBER($F40),$F40,FECHA.VALOR($F40)),IF(UPPER(TRIM($B40))="AUXILIAR DE COCINA",7,10),1,FESTIVOS!$D$3:$D$996))} -> 46066 | L40: =IF($F40="","",DATE(YEAR(EDATE($F40,IF(DAY($F40)>=17,1,0))),MONTH(EDATE($F40,IF(DAY($F40)>=17,1,0))),1)) -> 46054 | M40: =IF($K40="","",IF(OR($D40="",$D40<$F40),"PENDIENTE",IF($D40<=$K40,"A TIEMPO","FUERA DE TIEMPO"))) -> A TIEMPO
A41: HOYOS HIMITOLA VICTOR DANILO | B41: AUXILIAR DE SERVICIO | C41: CONTRATADO | D41: 46069 | E41: JESUS | F41: 46062 | G41: COLINA | H41: PUERTAS RAMIREZ VIVERLIS JOVANA | K41: {=IF(OR($B41="",$F41=""),"",WORKDAY.INTL(IF(ISNUMBER($F41),$F41,FECHA.VALOR($F41)),IF(UPPER(TRIM($B41))="AUXILIAR DE COCINA",7,10),1,FESTIVOS!$D$3:$D$996))} -> 46076 | L41: =IF($F41="","",DATE(YEAR(EDATE($F41,IF(DAY($F41)>=17,1,0))),MONTH(EDATE($F41,IF(DAY($F41)>=17,1,0))),1)) -> 46054 | M41: =IF($K41="","",IF(OR($D41="",$D41<$F41),"PENDIENTE",IF($D41<=$K41,"A TIEMPO","FUERA DE TIEMPO"))) -> A TIEMPO
A42: SUAREZ VELASQUEZ RAUL ANDRES | B42: AUXILIAR DE COCINA | C42: CONTRATADO | D42: 46065 | E42: SEBASTIAN | F42: 46062 | G42: SUPERNUMERARIO | H42: CASTRO BRAVO HEIDY ANDREA | K42: {=IF(OR($B42="",$F42=""),"",WORKDAY.INTL(IF(ISNUMBER($F42),$F42,FECHA.VALOR($F42)),IF(UPPER(TRIM($B42))="AUXILIAR DE COCINA",7,10),1,FESTIVOS!$D$3:$D$996))} -> 46071 | L42: =IF($F42="","",DATE(YEAR(EDATE($F42,IF(DAY($F42)>=17,1,0))),MONTH(EDATE($F42,IF(DAY($F42)>=17,1,0))),1)) -> 46054 | M42: =IF($K42="","",IF(OR($D42="",$D42<$F42),"PENDIENTE",IF($D42<=$K42,"A TIEMPO","FUERA DE TIEMPO"))) -> A TIEMPO
A43: QUIROZ BOLIVAR JOSE MIGUEL | B43: AUXILIAR DE COCINA | C43: CONTRATADO | D43: 46065 | E43: SEBASTIAN | F43: 46062 | G43: SUPERNUMERARIO | H43: ORTEGA OSORIO LEONARDO JOSE | K43: {=IF(OR($B43="",$F43=""),"",WORKDAY.INTL(IF(ISNUMBER($F43),$F43,FECHA.VALOR($F43)),IF(UPPER(TRIM($B43))="AUXILIAR DE COCINA",7,10),1,FESTIVOS!$D$3:$D$996))} -> 46071 | L43: =IF($F43="","",DATE(YEAR(EDATE($F43,IF(DAY($F43)>=17,1,0))),MONTH(EDATE($F43,IF(DAY($F43)>=17,1,0))),1)) -> 46054 | M43: =IF($K43="","",IF(OR($D43="",$D43<$F43),"PENDIENTE",IF($D43<=$K43,"A TIEMPO","FUERA DE TIEMPO"))) -> A TIEMPO
A44: MAULETH CRUZ YINETH PAOLA | B44: AUXILIAR DE COCINA | C44: CONTRATADO | D44: 46069 | E44: SEBASTIAN | F44: 46062 | G44: SUPERNUMERARIO | H44: GRANADOS CERVERA ROSA ANGELICA | K44: {=IF(OR($B44="",$F44=""),"",WORKDAY.INTL(IF(ISNUMBER($F44),$F44,FECHA.VALOR($F44)),IF(UPPER(TRIM($B44))="AUXILIAR DE COCINA",7,10),1,FESTIVOS!$D$3:$D$996))} -> 46071 | L44: =IF($F44="","",DATE(YEAR(EDATE($F44,IF(DAY($F44)>=17,1,0))),MONTH(EDATE($F44,IF(DAY($F44)>=17,1,0))),1)) -> 46054 | M44: =IF($K44="","",IF(OR($D44="",$D44<$F44),"PENDIENTE",IF($D44<=$K44,"A TIEMPO","FUERA DE TIEMPO"))) -> A TIEMPO
A45: SOTO AYALA JUAN CARLOS | B45: AUXILIAR DE COCINA | C45: CONTRATADO | D45: 46069 | E45: SEBASTIAN | F45: 46064 | G45: SUPERNUMERARIO | H45: QUIROZ OROZCO ANA MARIA | K45: {=IF(OR($B45="",$F45=""),"",WORKDAY.INTL(IF(ISNUMBER($F45),$F45,FECHA.VALOR($F45)),IF(UPPER(TRIM($B45))="AUXILIAR DE COCINA",7,10),1,FESTIVOS!$D$3:$D$996))} -> 46073 | L45: =IF($F45="","",DATE(YEAR(EDATE($F45,IF(DAY($F45)>=17,1,0))),MONTH(EDATE($F45,IF(DAY($F45)>=17,1,0))),1)) -> 46054 | M45: =IF($K45="","",IF(OR($D45="",$D45<$F45),"PENDIENTE",IF($D45<=$K45,"A TIEMPO","FUERA DE TIEMPO"))) -> A TIEMPO
A46: PACHECO MENDOZA YESICA MILENA | B46: AUXILIAR DE COCINA | C46: CONTRATADO | D46: 46069 | E46: SEBASTIAN | F46: 46064 | G46: SUPERNUMERARIO | H46: BUELVAS MADERA YURANIS YOENIS | K46: {=IF(OR($B46="",$F46=""),"",WORKDAY.INTL(IF(ISNUMBER($F46),$F46,FECHA.VALOR($F46)),IF(UPPER(TRIM($B46))="AUXILIAR DE COCINA",7,10),1,FESTIVOS!$D$3:$D$996))} -> 46073 | L46: =IF($F46="","",DATE(YEAR(EDATE($F46,IF(DAY($F46)>=17,1,0))),MONTH(EDATE($F46,IF(DAY($F46)>=17,1,0))),1)) -> 46054 | M46: =IF($K46="","",IF(OR($D46="",$D46<$F46),"PENDIENTE",IF($D46<=$K46,"A TIEMPO","FUERA DE TIEMPO"))) -> A TIEMPO
